Workbook

Sheet COVER
B2: MODEL KONSEPTUAL EVALUASI KINERJA PERAWAT Berbasis Klasterisasi & Hybrid MCDM (AHP–WP–TOPSIS)
B3: Fatkhurrochman, S.Kom, M.Kom | 2026
B5: NAVIGASI SHEET
B6: ▶ TAHAP 1 – K-MEANS | C6: Klasterisasi pola kinerja perawat (K-Means, k=3)
B7: ▶ TAHAP 2 – AHP | C7: Pembobotan kriteria AHP + uji Consistency Ratio
B8: ▶ TAHAP 3 – WP | C8: Agregasi nilai kinerja Weighted Product
B9: ▶ TAHAP 4 – TOPSIS | C9: Validasi pemeringkatan TOPSIS
B10: ▶ TAHAP 5 – MODEL | C10: Rekapitulasi final & Model Konseptual

Sheet TAHAP 1 – K-MEANS
B1: TAHAP 1: KLASTERISASI POLA KINERJA PERAWAT (K-MEANS CLUSTERING)
B2: Algoritma K-Means | 7 Kriteria | k = 3 Klaster | Silhouette Score ≥ 0.5
B4: A. DATA KINERJA PERAWAT (Skala 1–10) — Input Hardcode pada C1–C7
B5: No | C5: Nama Perawat | D5: C1 Komp. Klinis | E5: C2 Profesionalisme | F5: C3 Kolaborasi Tim | G5: C4 Orientasi Hasil | H5: C5 Keselamatan | I5: C6 Mgmt Waktu | J5: C7 Komunikasi | K5: Total Skor | L5: Rata-rata | M5: Klaster
B6: 1 | C6: Andi Setiawan | D6: 8 | E6: 7 | F6: 9 | G6: 8 | H6: 9 | I6: 7 | J6: 8 | K6: =SUM(D6:J6) -> 56 | L6: =AVERAGE(D6:J6) -> 8 | M6: =J25 -> K1
B7: 2 | C7: Budi Santoso | D7: 5 | E7: 6 | F7: 5 | G7: 6 | H7: 5 | I7: 6 | J7: 5 | K7: =SUM(D7:J7) -> 38 | L7: =AVERAGE(D7:J7) -> 5.4285714 | M7: =J26 -> K3
B8: 3 | C8: Citra Dewi | D8: 9 | E8: 9 | F8: 8 | G8: 9 | H8: 9 | I8: 8 | J8: 9 | K8: =SUM(D8:J8) -> 61 | L8: =AVERAGE(D8:J8) -> 8.7142857 | M8: =J27 -> K1
B9: 4 | C9: Dian Pratiwi | D9: 6 | E9: 5 | F9: 6 | G9: 5 | H9: 6 | I9: 5 | J9: 6 | K9: =SUM(D9:J9) -> 39 | L9: =AVERAGE(D9:J9) -> 5.5714286 | M9: =J28 -> K2
B10: 5 | C10: Eko Wahyudi | D10: 7 | E10: 8 | F10: 7 | G10: 8 | H10: 7 | I10: 8 | J10: 7 | K10: =SUM(D10:J10) -> 52 | L10: =AVERAGE(D10:J10) -> 7.4285714 | M10: =J29 -> K2
B11: 6 | C11: Fitri Handayani | D11: 4 | E11: 5 | F11: 4 | G11: 5 | H11: 4 | I11: 5 | J11: 4 | K11: =SUM(D11:J11) -> 31 | L11: =AVERAGE(D11:J11) -> 4.4285714 | M11: =J30 -> K3
B12: 7 | C12: Galih Nugroho | D12: 9 | E12: 8 | F12: 9 | G12: 9 | H12: 8 | I12: 9 | J12: 8 | K12: =SUM(D12:J12) -> 60 | L12: =AVERAGE(D12:J12) -> 8.5714286 | M12: =J31 -> K1
B13: 8 | C13: Hana Putri | D13: 6 | E13: 6 | F13: 7 | G13: 6 | H13: 7 | I13: 6 | J13: 7 | K13: =SUM(D13:J13) -> 45 | L13: =AVERAGE(D13:J13) -> 6.4285714 | M13: =J32 -> K2
B14: 9 | C14: Indra Kusuma | D14: 8 | E14: 9 | F14: 8 | G14: 8 | H14: 9 | I14: 9 | J14: 8 | K14: =SUM(D14:J14) -> 59 | L14: =AVERAGE(D14:J14) -> 8.4285714 | M14: =J33 -> K1
B15: 10 | C15: Joko Purnomo | D15: 5 | E15: 4 | F15: 5 | G15: 4 | H15: 5 | I15: 4 | J15: 5 | K15: =SUM(D15:J15) -> 32 | L15: =AVERAGE(D15:J15) -> 4.5714286 | M15: =J34 -> K3
B17: B. CENTROID K-MEANS (Hasil Iterasi Final) — Input Pakar/Algoritma
B18: Klaster | C18: C1 | D18: C2 | E18: C3 | F18: C4 | G18: C5 | H18: C6 | I18: C7 | J18: Label
B19: K1 (Tinggi) | C19: 8.5 | D19: 8.25 | E19: 8.5 | F19: 8.5 | G19: 8.75 | H19: 8.25 | I19: 8.25 | J19: Kinerja TINGGI
B20: K2 (Sedang) | C20: 6.3333 | D20: 6.3333 | E20: 6.6667 | F20: 6.3333 | G20: 6.6667 | H20: 6.3333 | I20: 6.6667 | J20: Kinerja SEDANG
B21: K3 (Rendah) | C21: 4.6667 | D21: 5 | E21: 4.6667 | F21: 5 | G21: 4.6667 | H21: 5 | I21: 4.6667 | J21: Kinerja RENDAH
B23: C. JARAK EUCLIDEAN KE CENTROID (Formula Excel) & PENUGASAN KLASTER
B24: No | C24: Perawat | D24: d² → K1 | E24: d² → K2 | F24: d² → K3 | G24: D→K1 | H24: D→K2 | I24: D→K3 | J24: Klaster Terdekat | K24: Label Klaster
B25: 1 | C25: ='TAHAP 1 – K-MEANS'!C6 -> Andi Setiawan | D25: =(D6-C19)^2+(D6-D19)^2+(D6-E19)^2+(D6-F19)^2+(D6-G19)^2+(D6-H19)^2+(D6-I19)^2 -> 1.5 | E25: =(D6-C20)^2+(D6-D20)^2+(D6-E20)^2+(D6-F20)^2+(D6-G20)^2+(D6-H20)^2+(D6-I20)^2 -> 16.444622 | F25: =(D6-C21)^2+(D6-D21)^2+(D6-E21)^2+(D6-F21)^2+(D6-G21)^2+(D6-H21)^2+(D6-I21)^2 -> 71.443556 | G25: =SQRT(D25) -> 1.2247449 | H25: =SQRT(E25) -> 4.0551969 | I25: =SQRT(F25) -> 8.452429 | J25: =IF(AND(G25<=H25,G25<=I25),"K1",IF(H25<=I25,"K2","K3")) -> K1 | K25: =IF(J25="K1","TINGGI",IF(J25="K2","SEDANG","RENDAH")) -> TINGGI
B26: 2 | C26: ='TAHAP 1 – K-MEANS'!C7 -> Budi Santoso | D26: =(D7-C19)^2+(D7-D19)^2+(D7-E19)^2+(D7-F19)^2+(D7-G19)^2+(D7-H19)^2+(D7-I19)^2 -> 82.5 | E26: =(D7-C20)^2+(D7-D20)^2+(D7-E20)^2+(D7-F20)^2+(D7-G20)^2+(D7-H20)^2+(D7-I20)^2 -> 15.444422 | F26: =(D7-C21)^2+(D7-D21)^2+(D7-E21)^2+(D7-F21)^2+(D7-G21)^2+(D7-H21)^2+(D7-I21)^2 -> 0.44435556 | G26: =SQRT(D26) -> 9.0829511 | H26: =SQRT(E26) -> 3.9299392 | I26: =SQRT(F26) -> 0.6666 | J26: =IF(AND(G26<=H26,G26<=I26),"K1",IF(H26<=I26,"K2","K3")) -> K3 | K26: =IF(J26="K1","TINGGI",IF(J26="K2","SEDANG","RENDAH")) -> RENDAH
B27: 3 | C27: ='TAHAP 1 – K-MEANS'!C8 -> Citra Dewi | D27: =(D8-C19)^2+(D8-D19)^2+(D8-E19)^2+(D8-F19)^2+(D8-G19)^2+(D8-H19)^2+(D8-I19)^2 -> 2.5 | E27: =(D8-C20)^2+(D8-D20)^2+(D8-E20)^2+(D8-F20)^2+(D8-G20)^2+(D8-H20)^2+(D8-I20)^2 -> 44.778022 | F27: =(D8-C21)^2+(D8-D21)^2+(D8-E21)^2+(D8-F21)^2+(D8-G21)^2+(D8-H21)^2+(D8-I21)^2 -> 123.10996 | G27: =SQRT(D27) -> 1.5811388 | H27: =SQRT(E27) -> 6.6916382 | I27: =SQRT(F27) -> 11.095493 | J27: =IF(AND(G27<=H27,G27<=I27),"K1",IF(H27<=I27,"K2","K3")) -> K1 | K27: =IF(J27="K1","TINGGI",IF(J27="K2","SEDANG","RENDAH")) -> TINGGI
B28: 4 | C28: ='TAHAP 1 – K-MEANS'!C9 -> Dian Pratiwi | D28: =(D9-C19)^2+(D9-D19)^2+(D9-E19)^2+(D9-F19)^2+(D9-G19)^2+(D9-H19)^2+(D9-I19)^2 -> 41.5 | E28: =(D9-C20)^2+(D9-D20)^2+(D9-E20)^2+(D9-F20)^2+(D9-G20)^2+(D9-H20)^2+(D9-I20)^2 -> 1.7778222 | F28: =(D9-C21)^2+(D9-D21)^2+(D9-E21)^2+(D9-F21)^2+(D9-G21)^2+(D9-H21)^2+(D9-I21)^2 -> 10.110756 | G28: =SQRT(D28) -> 6.4420494 | H28: =SQRT(E28) -> 1.33335 | I28: =SQRT(F28) -> 3.1797414 | J28: =IF(AND(G28<=H28,G28<=I28),"K1",IF(H28<=I28,"K2","K3")) -> K2 | K28: =IF(J28="K1","TINGGI",IF(J28="K2","SEDANG","RENDAH")) -> SEDANG
B29: 5 | C29: ='TAHAP 1 – K-MEANS'!C10 -> Eko Wahyudi | D29: =(D10-C19)^2+(D10-D19)^2+(D10-E19)^2+(D10-F19)^2+(D10-G19)^2+(D10-H19)^2+(D10-I19)^2 -> 14.5 | E29: =(D10-C20)^2+(D10-D20)^2+(D10-E20)^2+(D10-F20)^2+(D10-G20)^2+(D10-H20)^2+(D10-I20)^2 -> 2.1112222 | F29: =(D10-C21)^2+(D10-D21)^2+(D10-E21)^2+(D10-F21)^2+(D10-G21)^2+(D10-H21)^2+(D10-I21)^2 -> 33.777156 | G29: =SQRT(D29) -> 3.8078866 | H29: =SQRT(E29) -> 1.4530046 | I29: =SQRT(F29) -> 5.8118117 | J29: =IF(AND(G29<=H29,G29<=I29),"K1",IF(H29<=I29,"K2","K3")) -> K2 | K29: =IF(J29="K1","TINGGI",IF(J29="K2","SEDANG","RENDAH")) -> SEDANG
B30: 6 | C30: ='TAHAP 1 – K-MEANS'!C11 -> Fitri Handayani | D30: =(D11-C19)^2+(D11-D19)^2+(D11-E19)^2+(D11-F19)^2+(D11-G19)^2+(D11-H19)^2+(D11-I19)^2 -> 137.5 | E30: =(D11-C20)^2+(D11-D20)^2+(D11-E20)^2+(D11-F20)^2+(D11-G20)^2+(D11-H20)^2+(D11-I20)^2 -> 43.111022 | F30: =(D11-C21)^2+(D11-D21)^2+(D11-E21)^2+(D11-F21)^2+(D11-G21)^2+(D11-H21)^2+(D11-I21)^2 -> 4.7779556 | G30: =SQRT(D30) -> 11.726039 | H30: =SQRT(E30) -> 6.5658984 | I30: =SQRT(F30) -> 2.1858535 | J30: =IF(AND(G30<=H30,G30<=I30),"K1",IF(H30<=I30,"K2","K3")) -> K3 | K30: =IF(J30="K1","TINGGI",IF(J30="K2","SEDANG","RENDAH")) -> RENDAH
B31: 7 | C31: ='TAHAP 1 – K-MEANS'!C12 -> Galih Nugroho | D31: =(D12-C19)^2+(D12-D19)^2+(D12-E19)^2+(D12-F19)^2+(D12-G19)^2+(D12-H19)^2+(D12-I19)^2 -> 2.5 | E31: =(D12-C20)^2+(D12-D20)^2+(D12-E20)^2+(D12-F20)^2+(D12-G20)^2+(D12-H20)^2+(D12-I20)^2 -> 44.778022 | F31: =(D12-C21)^2+(D12-D21)^2+(D12-E21)^2+(D12-F21)^2+(D12-G21)^2+(D12-H21)^2+(D12-I21)^2 -> 123.10996 | G31: =SQRT(D31) -> 1.5811388 | H31: =SQRT(E31) -> 6.6916382 | I31: =SQRT(F31) -> 11.095493 | J31: =IF(AND(G31<=H31,G31<=I31),"K1",IF(H31<=I31,"K2","K3")) -> K1 | K31: =IF(J31="K1","TINGGI",IF(J31="K2","SEDANG","RENDAH")) -> TINGGI
B32: 8 | C32: ='TAHAP 1 – K-MEANS'!C13 -> Hana Putri | D32: =(D13-C19)^2+(D13-D19)^2+(D13-E19)^2+(D13-F19)^2+(D13-G19)^2+(D13-H19)^2+(D13-I19)^2 -> 41.5 | E32: =(D13-C20)^2+(D13-D20)^2+(D13-E20)^2+(D13-F20)^2+(D13-G20)^2+(D13-H20)^2+(D13-I20)^2 -> 1.7778222 | F32: =(D13-C21)^2+(D13-D21)^2+(D13-E21)^2+(D13-F21)^2+(D13-G21)^2+(D13-H21)^2+(D13-I21)^2 -> 10.110756 | G32: =SQRT(D32) -> 6.4420494 | H32: =SQRT(E32) -> 1.33335 | I32: =SQRT(F32) -> 3.1797414 | J32: =IF(AND(G32<=H32,G32<=I32),"K1",IF(H32<=I32,"K2","K3")) -> K2 | K32: =IF(J32="K1","TINGGI",IF(J32="K2","SEDANG","RENDAH")) -> SEDANG
B33: 9 | C33: ='TAHAP 1 – K-MEANS'!C14 -> Indra Kusuma | D33: =(D14-C19)^2+(D14-D19)^2+(D14-E19)^2+(D14-F19)^2+(D14-G19)^2+(D14-H19)^2+(D14-I19)^2 -> 1.5 | E33: =(D14-C20)^2+(D14-D20)^2+(D14-E20)^2+(D14-F20)^2+(D14-G20)^2+(D14-H20)^2+(D14-I20)^2 -> 16.444622 | F33: =(D14-C21)^2+(D14-D21)^2+(D14-E21)^2+(D14-F21)^2+(D14-G21)^2+(D14-H21)^2+(D14-I21)^2 -> 71.443556 | G33: =SQRT(D33) -> 1.2247449 | H33: =SQRT(E33) -> 4.0551969 | I33: =SQRT(F33) -> 8.452429 | J33: =IF(AND(G33<=H33,G33<=I33),"K1",IF(H33<=I33,"K2","K3")) -> K1 | K33: =IF(J33="K1","TINGGI",IF(J33="K2","SEDANG","RENDAH")) -> TINGGI
B34: 10 | C34: ='TAHAP 1 – K-MEANS'!C15 -> Joko Purnomo | D34: =(D15-C19)^2+(D15-D19)^2+(D15-E19)^2+(D15-F19)^2+(D15-G19)^2+(D15-H19)^2+(D15-I19)^2 -> 82.5 | E34: =(D15-C20)^2+(D15-D20)^2+(D15-E20)^2+(D15-F20)^2+(D15-G20)^2+(D15-H20)^2+(D15-I20)^2 -> 15.444422 | F34: =(D15-C21)^2+(D15-D21)^2+(D15-E21)^2+(D15-F21)^2+(D15-G21)^2+(D15-H21)^2+(D15-I21)^2 -> 0.44435556 | G34: =SQRT(D34) -> 9.0829511 | H34: =SQRT(E34) -> 3.9299392 | I34: =SQRT(F34) -> 0.6666 | J34: =IF(AND(G34<=H34,G34<=I34),"K1",IF(H34<=I34,"K2","K3")) -> K3 | K34: =IF(J34="K1","TINGGI",IF(J34="K2","SEDANG","RENDAH")) -> RENDAH
B36: ✔ Silhouette Score (Dihitung Aktual) = 0.3219 → Klasterisasi Perlu Ditinjau
A38: D. LOG PROSES ITERASI K-MEANS (Dihitung dari Data Mentah — Bukan Hardcode)
A39: Centroid Awal dipilih berbasis domain (high/mid/low). Setiap iterasi: Langkah E (Assign) + Langkah M (Update Centroid). Berhenti saat label tidak berubah.
A40: Centroid Awal (Iterasi ke-0) — Titik Representatif Berbasis Domain
A41: Klaster | B41: Representatif (Init) | C41: C1 | D41: C2 | E41: C3 | F41: C4 | G41: C5 | H41: C6 | I41: C7
A42: K1 (awal) | B42: Citra Dewi | C42: 9 | D42: 9 | E42: 8 | F42: 9 | G42: 9 | H42: 8 | I42: 9
A43: K2 (awal) | B43: Hana Putri | C43: 6 | D43: 6 | E43: 7 | F43: 6 | G43: 7 | H43: 6 | I43: 7
A44: K3 (awal) | B44: Fitri Handayani | C44: 4 | D44: 5 | E44: 4 | F44: 5 | G44: 4 | H44: 5 | I44: 4
A46: ITERASI 1 — Label BERUBAH → Centroid diperbarui
...

Sheet TAHAP 2 – AHP
B1: TAHAP 2: PEMBOBOTAN KRITERIA – ANALYTICAL HIERARCHY PROCESS (AHP)
B2: Pairwise Matrix = Input Pakar | Normalisasi & CR = Formula Excel
B4: A. MATRIKS PERBANDINGAN BERPASANGAN — Input Pakar (Skala 1–9 Saaty)
B5: Kriteria / Kriteria | C5: C1: Komp. Klinis | D5: C2: Profesionalisme | E5: C3: Kolaborasi Tim | F5: C4: Orientasi Hasil | G5: C5: Keselamatan | H5: C6: Mgmt Waktu | I5: C7: Komunikasi
B6: C1: Komp. Klinis | C6: 1 | D6: 3 | E6: 5 | F6: 7 | G6: 5 | H6: 7 | I6: 9
B7: C2: Profesionalisme | C7: =1/D6 -> 0.33333333 | D7: 1 | E7: 3 | F7: 5 | G7: 3 | H7: 5 | I7: 7
B8: C3: Kolaborasi Tim | C8: =1/E6 -> 0.2 | D8: =1/E7 -> 0.33333333 | E8: 1 | F8: 3 | G8: 1 | H8: 3 | I8: 5
B9: C4: Orientasi Hasil | C9: =1/F6 -> 0.14285714 | D9: =1/F7 -> 0.2 | E9: =1/F8 -> 0.33333333 | F9: 1 | G9: 0.33333333 | H9: 1 | I9: 3
B10: C5: Keselamatan | C10: =1/G6 -> 0.2 | D10: =1/G7 -> 0.33333333 | E10: =1/G8 -> 1 | F10: =1/G9 -> 3 | G10: 1 | H10: 3 | I10: 5
B11: C6: Mgmt Waktu | C11: =1/H6 -> 0.14285714 | D11: =1/H7 -> 0.2 | E11: =1/H8 -> 0.33333333 | F11: =1/H9 -> 1 | G11: =1/H10 -> 0.33333333 | H11: 1 | I11: 3
B12: C7: Komunikasi | C12: =1/I6 -> 0.11111111 | D12: =1/I7 -> 0.14285714 | E12: =1/I8 -> 0.2 | F12: =1/I9 -> 0.33333333 | G12: =1/I10 -> 0.2 | H12: =1/I11 -> 0.33333333 | I12: 1
B13: JUMLAH KOLOM | C13: =SUM(C6:C12) -> 2.1301587 | D13: =SUM(D6:D12) -> 5.2095238 | E13: =SUM(E6:E12) -> 10.866667 | F13: =SUM(F6:F12) -> 20.333333 | G13: =SUM(G6:G12) -> 10.866667 | H13: =SUM(H6:H12) -> 20.333333 | I13: =SUM(I6:I12) -> 33
B15: B. MATRIKS NORMALISASI (rij = xij / jumlah kolom-j) & BOBOT PRIORITAS
B16: Kriteria | C16: C1: Komp. Klinis | D16: C2: Profesionalisme | E16: C3: Kolaborasi Tim | F16: C4: Orientasi Hasil | G16: C5: Keselamatan | H16: C6: Mgmt Waktu | I16: C7: Komunikasi | J16: Bobot (W)
B17: C1: Komp. Klinis | C17: =C6/C13 -> 0.46944858 | D17: =D6/D13 -> 0.57586837 | E17: =E6/E13 -> 0.4601227 | F17: =F6/F13 -> 0.3442623 | G17: =G6/G13 -> 0.4601227 | H17: =H6/H13 -> 0.3442623 | I17: =I6/I13 -> 0.27272727 | J17: =AVERAGE(C17:I17) -> 0.41811632 | P17: =C6/C13 -> 0.46944858 | Q17: =D6/D13 -> 0.57586837 | R17: =E6/E13 -> 0.4601227 | S17: =F6/F13 -> 0.3442623 | T17: =G6/G13 -> 0.4601227 | U17: =H6/H13 -> 0.3442623 | V17: =I6/I13 -> 0.27272727
B18: C2: Profesionalisme | C18: =C7/C13 -> 0.15648286 | D18: =D7/D13 -> 0.19195612 | E18: =E7/E13 -> 0.27607362 | F18: =F7/F13 -> 0.24590164 | G18: =G7/G13 -> 0.27607362 | H18: =H7/H13 -> 0.24590164 | I18: =I7/I13 -> 0.21212121 | J18: =AVERAGE(C18:I18) -> 0.22921582 | P18: =C7/C13 -> 0.15648286 | Q18: =D7/D13 -> 0.19195612 | R18: =E7/E13 -> 0.27607362 | S18: =F7/F13 -> 0.24590164 | T18: =G7/G13 -> 0.27607362 | U18: =H7/H13 -> 0.24590164 | V18: =I7/I13 -> 0.21212121
B19: C3: Kolaborasi Tim | C19: =C8/C13 -> 0.093889717 | D19: =D8/D13 -> 0.063985375 | E19: =E8/E13 -> 0.09202454 | F19: =F8/F13 -> 0.14754098 | G19: =G8/G13 -> 0.09202454 | H19: =H8/H13 -> 0.14754098 | I19: =I8/I13 -> 0.15151515 | J19: =AVERAGE(C19:I19) -> 0.1126459 | P19: =C8/C13 -> 0.093889717 | Q19: =D8/D13 -> 0.063985375 | R19: =E8/E13 -> 0.09202454 | S19: =F8/F13 -> 0.14754098 | T19: =G8/G13 -> 0.09202454 | U19: =H8/H13 -> 0.14754098 | V19: =I8/I13 -> 0.15151515
B20: C4: Orientasi Hasil | C20: =C9/C13 -> 0.067064083 | D20: =D9/D13 -> 0.038391225 | E20: =E9/E13 -> 0.030674847 | F20: =F9/F13 -> 0.049180328 | G20: =G9/G13 -> 0.030674847 | H20: =H9/H13 -> 0.049180328 | I20: =I9/I13 -> 0.090909091 | J20: =AVERAGE(C20:I20) -> 0.050867821 | P20: =C9/C13 -> 0.067064083 | Q20: =D9/D13 -> 0.038391225 | R20: =E9/E13 -> 0.030674847 | S20: =F9/F13 -> 0.049180328 | T20: =G9/G13 -> 0.030674847 | U20: =H9/H13 -> 0.049180328 | V20: =I9/I13 -> 0.090909091
B21: C5: Keselamatan | C21: =C10/C13 -> 0.093889717 | D21: =D10/D13 -> 0.063985375 | E21: =E10/E13 -> 0.09202454 | F21: =F10/F13 -> 0.14754098 | G21: =G10/G13 -> 0.09202454 | H21: =H10/H13 -> 0.14754098 | I21: =I10/I13 -> 0.15151515 | J21: =AVERAGE(C21:I21) -> 0.1126459 | P21: =C10/C13 -> 0.093889717 | Q21: =D10/D13 -> 0.063985375 | R21: =E10/E13 -> 0.09202454 | S21: =F10/F13 -> 0.14754098 | T21: =G10/G13 -> 0.09202454 | U21: =H10/H13 -> 0.14754098 | V21: =I10/I13 -> 0.15151515
B22: C6: Mgmt Waktu | C22: =C11/C13 -> 0.067064083 | D22: =D11/D13 -> 0.038391225 | E22: =E11/E13 -> 0.030674847 | F22: =F11/F13 -> 0.049180328 | G22: =G11/G13 -> 0.030674847 | H22: =H11/H13 -> 0.049180328 | I22: =I11/I13 -> 0.090909091 | J22: =AVERAGE(C22:I22) -> 0.050867821 | P22: =C11/C13 -> 0.067064083 | Q22: =D11/D13 -> 0.038391225 | R22: =E11/E13 -> 0.030674847 | S22: =F11/F13 -> 0.049180328 | T22: =G11/G13 -> 0.030674847 | U22: =H11/H13 -> 0.049180328 | V22: =I11/I13 -> 0.090909091
B23: C7: Komunikasi | C23: =C12/C13 -> 0.052160954 | D23: =D12/D13 -> 0.027422303 | E23: =E12/E13 -> 0.018404908 | F23: =F12/F13 -> 0.016393443 | G23: =G12/G13 -> 0.018404908 | H23: =H12/H13 -> 0.016393443 | I23: =I12/I13 -> 0.03030303 | J23: =AVERAGE(C23:I23) -> 0.025640427 | P23: =C12/C13 -> 0.052160954 | Q23: =D12/D13 -> 0.027422303 | R23: =E12/E13 -> 0.018404908 | S23: =F12/F13 -> 0.016393443 | T23: =G12/G13 -> 0.018404908 | U23: =H12/H13 -> 0.016393443 | V23: =I12/I13 -> 0.03030303
B25: C. UJI KONSISTENSI (Consistency Ratio — CR < 0.1)
B26: Weighted Sum Vector (WSV) | C26: =C6*J17+D6*J18+E6*J19+F6*J20+G6*J21+H6*J22+I6*J23 -> 3.1751361 | D26: =C7*J17+D7*J18+E7*J19+F7*J20+G7*J21+H7*J22+I7*J23 -> 1.7326245 | E26: =C8*J17+D8*J18+E8*J19+F8*J20+G8*J21+H8*J22+I8*J23 -> 0.81872939 | F26: =C9*J17+D9*J18+E9*J19+F9*J20+G9*J21+H9*J22+I9*J23 -> 0.35932825 | G26: =C10*J17+D10*J18+E10*J19+F10*J20+G10*J21+H10*J22+I10*J23 -> 0.81872939 | H26: =C11*J17+D11*J18+E11*J19+F11*J20+G11*J21+H11*J22+I11*J23 -> 0.35932825 | I26: =C12*J17+D12*J18+E12*J19+F12*J20+G12*J21+H12*J22+I12*J23 -> 0.18381315
B27: Lambda Vector (λi = WSV / Wi) | C27: =C26/J17 -> 7.5939062 | D27: =D26/J18 -> 7.5589222 | E27: =E26/J19 -> 7.2681687 | F27: =F26/J20 -> 7.06396 | G27: =G26/J21 -> 7.2681687 | H27: =H26/J22 -> 7.06396 | I27: =I26/J23 -> 7.1688803
B28: n (Jumlah Kriteria) | C28: 7
B29: λmax = AVERAGE(λi) | C29: =AVERAGE(C27:I27) -> 7.2837094
B30: CI = (λmax − n) / (n−1) | C30: =(C29-C28)/(C28-1) -> 0.047284907
B31: RI (n=7, tabel Saaty) | C31: 1.32
B32: CR = CI / RI | C32: =C30/C31 -> 0.0358219
B33: Status Konsistensi | C33: =IF(C32<0.1,"✔ KONSISTEN (CR < 0.1)","✘ TIDAK KONSISTEN") -> ✔ KONSISTEN (CR < 0.1)

Sheet TAHAP 3 – WP
B1: TAHAP 3: AGREGASI NILAI KINERJA — WEIGHTED PRODUCT (WP)
B2: Formula: Si = ∏(Xij ^ Wj) | Bobot diambil dari Sheet AHP (formula referencing)
B4: A. BOBOT KRITERIA (Referensi dari Sheet TAHAP 2 – AHP)
B5: Kriteria/Perawat | C5: C1 | D5: C2 | E5: C3 | F5: C4 | G5: C5 | H5: C6 | I5: C7 | J5: WP Score (Si) | K5: Rank WP | L5: Klaster
B6: Bobot (W) | C6: ='TAHAP 2 – AHP'!J17 -> 0.41811632 | D6: ='TAHAP 2 – AHP'!J18 -> 0.22921582 | E6: ='TAHAP 2 – AHP'!J19 -> 0.1126459 | F6: ='TAHAP 2 – AHP'!J20 -> 0.050867821 | G6: ='TAHAP 2 – AHP'!J21 -> 0.1126459 | H6: ='TAHAP 2 – AHP'!J22 -> 0.050867821 | I6: ='TAHAP 2 – AHP'!J23 -> 0.025640427
B7: B. DATA KINERJA & PERHITUNGAN WP SCORE
B8: No | C8: Nama Perawat | D8: C1 | E8: C2 | F8: C3 | G8: C4 | H8: C5 | I8: C6 | J8: C7 | K8: WP Score (Si) | L8: Rank WP | M8: Klaster
B9: 1 | C9: ='TAHAP 1 – K-MEANS'!C6 -> Andi Setiawan | D9: ='TAHAP 1 – K-MEANS'!D6 -> 8 | E9: ='TAHAP 1 – K-MEANS'!E6 -> 7 | F9: ='TAHAP 1 – K-MEANS'!F6 -> 9 | G9: ='TAHAP 1 – K-MEANS'!G6 -> 8 | H9: ='TAHAP 1 – K-MEANS'!H6 -> 9 | I9: ='TAHAP 1 – K-MEANS'!I6 -> 7 | J9: ='TAHAP 1 – K-MEANS'!J6 -> 8 | K9: =(D9^C6)*(E9^D6)*(F9^E6)*(G9^F6)*(H9^G6)*(I9^H6)*(J9^I6) -> 7.9135552 | L9: =RANK(K9,K9:K18,0) -> 4 | M9: ='TAHAP 1 – K-MEANS'!M6 -> K1
B10: 2 | C10: ='TAHAP 1 – K-MEANS'!C7 -> Budi Santoso | D10: ='TAHAP 1 – K-MEANS'!D7 -> 5 | E10: ='TAHAP 1 – K-MEANS'!E7 -> 6 | F10: ='TAHAP 1 – K-MEANS'!F7 -> 5 | G10: ='TAHAP 1 – K-MEANS'!G7 -> 6 | H10: ='TAHAP 1 – K-MEANS'!H7 -> 5 | I10: ='TAHAP 1 – K-MEANS'!I7 -> 6 | J10: ='TAHAP 1 – K-MEANS'!J7 -> 5 | K10: =(D10^C6)*(E10^D6)*(F10^E6)*(G10^F6)*(H10^G6)*(I10^H6)*(J10^I6) -> 5.310986 | L10: =RANK(K10,K9:K18,0) -> 8 | M10: ='TAHAP 1 – K-MEANS'!M7 -> K3
B11: 3 | C11: ='TAHAP 1 – K-MEANS'!C8 -> Citra Dewi | D11: ='TAHAP 1 – K-MEANS'!D8 -> 9 | E11: ='TAHAP 1 – K-MEANS'!E8 -> 9 | F11: ='TAHAP 1 – K-MEANS'!F8 -> 8 | G11: ='TAHAP 1 – K-MEANS'!G8 -> 9 | H11: ='TAHAP 1 – K-MEANS'!H8 -> 9 | I11: ='TAHAP 1 – K-MEANS'!I8 -> 8 | J11: ='TAHAP 1 – K-MEANS'!J8 -> 9 | K11: =(D11^C6)*(E11^D6)*(F11^E6)*(G11^F6)*(H11^G6)*(I11^H6)*(J11^I6) -> 8.8283262 | L11: =RANK(K11,K9:K18,0) -> 1 | M11: ='TAHAP 1 – K-MEANS'!M8 -> K1
B12: 4 | C12: ='TAHAP 1 – K-MEANS'!C9 -> Dian Pratiwi | D12: ='TAHAP 1 – K-MEANS'!D9 -> 6 | E12: ='TAHAP 1 – K-MEANS'!E9 -> 5 | F12: ='TAHAP 1 – K-MEANS'!F9 -> 6 | G12: ='TAHAP 1 – K-MEANS'!G9 -> 5 | H12: ='TAHAP 1 – K-MEANS'!H9 -> 6 | I12: ='TAHAP 1 – K-MEANS'!I9 -> 5 | J12: ='TAHAP 1 – K-MEANS'!J9 -> 6 | K12: =(D12^C6)*(E12^D6)*(F12^E6)*(G12^F6)*(H12^G6)*(I12^H6)*(J12^I6) -> 5.6486687 | L12: =RANK(K12,K9:K18,0) -> 7 | M12: ='TAHAP 1 – K-MEANS'!M9 -> K2
B13: 5 | C13: ='TAHAP 1 – K-MEANS'!C10 -> Eko Wahyudi | D13: ='TAHAP 1 – K-MEANS'!D10 -> 7 | E13: ='TAHAP 1 – K-MEANS'!E10 -> 8 | F13: ='TAHAP 1 – K-MEANS'!F10 -> 7 | G13: ='TAHAP 1 – K-MEANS'!G10 -> 8 | H13: ='TAHAP 1 – K-MEANS'!H10 -> 7 | I13: ='TAHAP 1 – K-MEANS'!I10 -> 8 | J13: ='TAHAP 1 – K-MEANS'!J10 -> 7 | K13: =(D13^C6)*(E13^D6)*(F13^E6)*(G13^F6)*(H13^G6)*(I13^H6)*(J13^I6) -> 7.3162841 | L13: =RANK(K13,K9:K18,0) -> 5 | M13: ='TAHAP 1 – K-MEANS'!M10 -> K2
B14: 6 | C14: ='TAHAP 1 – K-MEANS'!C11 -> Fitri Handayani | D14: ='TAHAP 1 – K-MEANS'!D11 -> 4 | E14: ='TAHAP 1 – K-MEANS'!E11 -> 5 | F14: ='TAHAP 1 – K-MEANS'!F11 -> 4 | G14: ='TAHAP 1 – K-MEANS'!G11 -> 5 | H14: ='TAHAP 1 – K-MEANS'!H11 -> 4 | I14: ='TAHAP 1 – K-MEANS'!I11 -> 5 | J14: ='TAHAP 1 – K-MEANS'!J11 -> 4 | K14: =(D14^C6)*(E14^D6)*(F14^E6)*(G14^F6)*(H14^G6)*(I14^H6)*(J14^I6) -> 4.3065798 | L14: =RANK(K14,K9:K18,0) -> 10 | M14: ='TAHAP 1 – K-MEANS'!M11 -> K3
B15: 7 | C15: ='TAHAP 1 – K-MEANS'!C12 -> Galih Nugroho | D15: ='TAHAP 1 – K-MEANS'!D12 -> 9 | E15: ='TAHAP 1 – K-MEANS'!E12 -> 8 | F15: ='TAHAP 1 – K-MEANS'!F12 -> 9 | G15: ='TAHAP 1 – K-MEANS'!G12 -> 9 | H15: ='TAHAP 1 – K-MEANS'!H12 -> 8 | I15: ='TAHAP 1 – K-MEANS'!I12 -> 9 | J15: ='TAHAP 1 – K-MEANS'!J12 -> 8 | K15: =(D15^C6)*(E15^D6)*(F15^E6)*(G15^F6)*(H15^G6)*(I15^H6)*(J15^I6) -> 8.6187414 | L15: =RANK(K15,K9:K18,0) -> 2 | M15: ='TAHAP 1 – K-MEANS'!M12 -> K1
B16: 8 | C16: ='TAHAP 1 – K-MEANS'!C13 -> Hana Putri | D16: ='TAHAP 1 – K-MEANS'!D13 -> 6 | E16: ='TAHAP 1 – K-MEANS'!E13 -> 6 | F16: ='TAHAP 1 – K-MEANS'!F13 -> 7 | G16: ='TAHAP 1 – K-MEANS'!G13 -> 6 | H16: ='TAHAP 1 – K-MEANS'!H13 -> 7 | I16: ='TAHAP 1 – K-MEANS'!I13 -> 6 | J16: ='TAHAP 1 – K-MEANS'!J13 -> 7 | K16: =(D16^C6)*(E16^D6)*(F16^E6)*(G16^F6)*(H16^G6)*(I16^H6)*(J16^I6) -> 6.2366354 | L16: =RANK(K16,K9:K18,0) -> 6 | M16: ='TAHAP 1 – K-MEANS'!M13 -> K2
B17: 9 | C17: ='TAHAP 1 – K-MEANS'!C14 -> Indra Kusuma | D17: ='TAHAP 1 – K-MEANS'!D14 -> 8 | E17: ='TAHAP 1 – K-MEANS'!E14 -> 9 | F17: ='TAHAP 1 – K-MEANS'!F14 -> 8 | G17: ='TAHAP 1 – K-MEANS'!G14 -> 8 | H17: ='TAHAP 1 – K-MEANS'!H14 -> 9 | I17: ='TAHAP 1 – K-MEANS'!I14 -> 9 | J17: ='TAHAP 1 – K-MEANS'!J14 -> 8 | K17: =(D17^C6)*(E17^D6)*(F17^E6)*(G17^F6)*(H17^G6)*(I17^H6)*(J17^I6) -> 8.3787473 | L17: =RANK(K17,K9:K18,0) -> 3 | M17: ='TAHAP 1 – K-MEANS'!M14 -> K1
B18: 10 | C18: ='TAHAP 1 – K-MEANS'!C15 -> Joko Purnomo | D18: ='TAHAP 1 – K-MEANS'!D15 -> 5 | E18: ='TAHAP 1 – K-MEANS'!E15 -> 4 | F18: ='TAHAP 1 – K-MEANS'!F15 -> 5 | G18: ='TAHAP 1 – K-MEANS'!G15 -> 4 | H18: ='TAHAP 1 – K-MEANS'!H15 -> 5 | I18: ='TAHAP 1 – K-MEANS'!I15 -> 4 | J18: ='TAHAP 1 – K-MEANS'!J15 -> 5 | K18: =(D18^C6)*(E18^D6)*(F18^E6)*(G18^F6)*(H18^G6)*(I18^H6)*(J18^I6) -> 4.6440565 | L18: =RANK(K18,K9:K18,0) -> 9 | M18: ='TAHAP 1 – K-MEANS'!M15 -> K3
B20: Catatan: Si dihitung via formula POWER non-linear. Rank via fungsi RANK(). Bobot = referensi AHP.

Sheet TAHAP 4 – TOPSIS
B1: TAHAP 4: VALIDASI PEMERINGKATAN — TOPSIS
B2: Semua langkah (normalisasi, pembobotan, D+, D−, Ci, Rank) = Formula Excel
B4: LANGKAH 1: NORMALISASI MATRIKS KEPUTUSAN rij = xij / √(Σ xij²)
B5: No | C5: Nama Perawat | D5: r_C1 | E5: r_C2 | F5: r_C3 | G5: r_C4 | H5: r_C5 | I5: r_C6 | J5: r_C7 | K5: D+ (Pos) | L5: D- (Neg) | M5: Ci (Kedekatan) | N5: Rank | O5: Klaster
B6: 1 | C6: ='TAHAP 3 – WP'!C9 -> Andi Setiawan | D6: ='TAHAP 3 – WP'!D9/C16 -> 0.36629484 | E6: ='TAHAP 3 – WP'!E9/D16 -> 0.32050798 | F6: ='TAHAP 3 – WP'!F9/E16 -> 0.40657856 | G6: ='TAHAP 3 – WP'!G9/F16 -> 0.36066785 | H6: ='TAHAP 3 – WP'!H9/G16 -> 0.39970403 | I6: ='TAHAP 3 – WP'!I9/H16 -> 0.32050798 | J6: ='TAHAP 3 – WP'!J9/I16 -> 0.36784039 | K6: =SQRT((D20-D30)^2+(E20-E30)^2+(F20-F30)^2+(G20-G30)^2+(H20-H30)^2+(I20-I30)^2+(J20-J30)^2) -> 0.028903896 | L6: =SQRT((D20-D31)^2+(E20-E31)^2+(F20-F31)^2+(G20-G31)^2+(H20-H31)^2+(I20-I31)^2+(J20-J31)^2) -> 0.091014558 | M6: =L6/(K6+L6) -> 0.75897041 | N6: =RANK(M6,M6:M15,0) -> 4 | O6: ='TAHAP 3 – WP'!M9 -> K1
B7: 2 | C7: ='TAHAP 3 – WP'!C10 -> Budi Santoso | D7: ='TAHAP 3 – WP'!D10/C16 -> 0.22893427 | E7: ='TAHAP 3 – WP'!E10/D16 -> 0.27472113 | F7: ='TAHAP 3 – WP'!F10/E16 -> 0.22587698 | G7: ='TAHAP 3 – WP'!G10/F16 -> 0.27050089 | H7: ='TAHAP 3 – WP'!H10/G16 -> 0.2220578 | I7: ='TAHAP 3 – WP'!I10/H16 -> 0.27472113 | J7: ='TAHAP 3 – WP'!J10/I16 -> 0.22990024 | K7: =SQRT((D21-D30)^2+(E21-E30)^2+(F21-F30)^2+(G21-G30)^2+(H21-H30)^2+(I21-I30)^2+(J21-J30)^2) -> 0.088252592 | L7: =SQRT((D21-D31)^2+(E21-E31)^2+(F21-F31)^2+(G21-G31)^2+(H21-H31)^2+(I21-I31)^2+(J21-J31)^2) -> 0.030035592 | M7: =L7/(K7+L7) -> 0.25391879 | N7: =RANK(M7,M6:M15,0) -> 8 | O7: ='TAHAP 3 – WP'!M10 -> K3
B8: 3 | C8: ='TAHAP 3 – WP'!C11 -> Citra Dewi | D8: ='TAHAP 3 – WP'!D11/C16 -> 0.41208169 | E8: ='TAHAP 3 – WP'!E11/D16 -> 0.41208169 | F8: ='TAHAP 3 – WP'!F11/E16 -> 0.36140316 | G8: ='TAHAP 3 – WP'!G11/F16 -> 0.40575134 | H8: ='TAHAP 3 – WP'!H11/G16 -> 0.39970403 | I8: ='TAHAP 3 – WP'!I11/H16 -> 0.36629484 | J8: ='TAHAP 3 – WP'!J11/I16 -> 0.41382044 | K8: =SQRT((D22-D30)^2+(E22-E30)^2+(F22-F30)^2+(G22-G30)^2+(H22-H30)^2+(I22-I30)^2+(J22-J30)^2) -> 0.0055964919 | L8: =SQRT((D22-D31)^2+(E22-E31)^2+(F22-F31)^2+(G22-G31)^2+(H22-H31)^2+(I22-I31)^2+(J22-J31)^2) -> 0.11493153 | M8: =L8/(K8+L8) -> 0.95356688 | N8: =RANK(M8,M6:M15,0) -> 1 | O8: ='TAHAP 3 – WP'!M11 -> K1
B9: 4 | C9: ='TAHAP 3 – WP'!C12 -> Dian Pratiwi | D9: ='TAHAP 3 – WP'!D12/C16 -> 0.27472113 | E9: ='TAHAP 3 – WP'!E12/D16 -> 0.22893427 | F9: ='TAHAP 3 – WP'!F12/E16 -> 0.27105237 | G9: ='TAHAP 3 – WP'!G12/F16 -> 0.22541741 | H9: ='TAHAP 3 – WP'!H12/G16 -> 0.26646936 | I9: ='TAHAP 3 – WP'!I12/H16 -> 0.22893427 | J9: ='TAHAP 3 – WP'!J12/I16 -> 0.27588029 | K9: =SQRT((D23-D30)^2+(E23-E30)^2+(F23-F30)^2+(G23-G30)^2+(H23-H30)^2+(I23-I30)^2+(J23-J30)^2) -> 0.075515722 | L9: =SQRT((D23-D31)^2+(E23-E31)^2+(F23-F31)^2+(G23-G31)^2+(H23-H31)^2+(I23-I31)^2+(J23-J31)^2) -> 0.042380326 | M9: =L9/(K9+L9) -> 0.35947198 | N9: =RANK(M9,M6:M15,0) -> 7 | O9: ='TAHAP 3 – WP'!M12 -> K2
B10: 5 | C10: ='TAHAP 3 – WP'!C13 -> Eko Wahyudi | D10: ='TAHAP 3 – WP'!D13/C16 -> 0.32050798 | E10: ='TAHAP 3 – WP'!E13/D16 -> 0.36629484 | F10: ='TAHAP 3 – WP'!F13/E16 -> 0.31622777 | G10: ='TAHAP 3 – WP'!G13/F16 -> 0.36066785 | H10: ='TAHAP 3 – WP'!H13/G16 -> 0.31088091 | I10: ='TAHAP 3 – WP'!I13/H16 -> 0.36629484 | J10: ='TAHAP 3 – WP'!J13/I16 -> 0.32186034 | K10: =SQRT((D24-D30)^2+(E24-E30)^2+(F24-F30)^2+(G24-G30)^2+(H24-H30)^2+(I24-I30)^2+(J24-J30)^2) -> 0.042380326 | L10: =SQRT((D24-D31)^2+(E24-E31)^2+(F24-F31)^2+(G24-G31)^2+(H24-H31)^2+(I24-I31)^2+(J24-J31)^2) -> 0.075515722 | M10: =L10/(K10+L10) -> 0.64052802 | N10: =RANK(M10,M6:M15,0) -> 5 | O10: ='TAHAP 3 – WP'!M13 -> K2
B11: 6 | C11: ='TAHAP 3 – WP'!C14 -> Fitri Handayani | D11: ='TAHAP 3 – WP'!D14/C16 -> 0.18314742 | E11: ='TAHAP 3 – WP'!E14/D16 -> 0.22893427 | F11: ='TAHAP 3 – WP'!F14/E16 -> 0.18070158 | G11: ='TAHAP 3 – WP'!G14/F16 -> 0.22541741 | H11: ='TAHAP 3 – WP'!H14/G16 -> 0.17764624 | I11: ='TAHAP 3 – WP'!I14/H16 -> 0.22893427 | J11: ='TAHAP 3 – WP'!J14/I16 -> 0.1839202 | K11: =SQRT((D25-D30)^2+(E25-E30)^2+(F25-F30)^2+(G25-G30)^2+(H25-H30)^2+(I25-I30)^2+(J25-J30)^2) -> 0.11137177 | L11: =SQRT((D25-D31)^2+(E25-E31)^2+(F25-F31)^2+(G25-G31)^2+(H25-H31)^2+(I25-I31)^2+(J25-J31)^2) -> 0.010992286 | M11: =L11/(K11+L11) -> 0.089832635 | N11: =RANK(M11,M6:M15,0) -> 10 | O11: ='TAHAP 3 – WP'!M14 -> K3
B12: 7 | C12: ='TAHAP 3 – WP'!C15 -> Galih Nugroho | D12: ='TAHAP 3 – WP'!D15/C16 -> 0.41208169 | E12: ='TAHAP 3 – WP'!E15/D16 -> 0.36629484 | F12: ='TAHAP 3 – WP'!F15/E16 -> 0.40657856 | G12: ='TAHAP 3 – WP'!G15/F16 -> 0.40575134 | H12: ='TAHAP 3 – WP'!H15/G16 -> 0.35529247 | I12: ='TAHAP 3 – WP'!I15/H16 -> 0.41208169 | J12: ='TAHAP 3 – WP'!J15/I16 -> 0.36784039 | K12: =SQRT((D26-D30)^2+(E26-E30)^2+(F26-F30)^2+(G26-G30)^2+(H26-H30)^2+(I26-I30)^2+(J26-J30)^2) -> 0.011686071 | L12: =SQRT((D26-D31)^2+(E26-E31)^2+(F26-F31)^2+(G26-G31)^2+(H26-H31)^2+(I26-I31)^2+(J26-J31)^2) -> 0.11073421 | M12: =L12/(K12+L12) -> 0.90454139 | N12: =RANK(M12,M6:M15,0) -> 2 | O12: ='TAHAP 3 – WP'!M15 -> K1
B13: 8 | C13: ='TAHAP 3 – WP'!C16 -> Hana Putri | D13: ='TAHAP 3 – WP'!D16/C16 -> 0.27472113 | E13: ='TAHAP 3 – WP'!E16/D16 -> 0.27472113 | F13: ='TAHAP 3 – WP'!F16/E16 -> 0.31622777 | G13: ='TAHAP 3 – WP'!G16/F16 -> 0.27050089 | H13: ='TAHAP 3 – WP'!H16/G16 -> 0.31088091 | I13: ='TAHAP 3 – WP'!I16/H16 -> 0.27472113 | J13: ='TAHAP 3 – WP'!J16/I16 -> 0.32186034 | K13: =SQRT((D27-D30)^2+(E27-E30)^2+(F27-F30)^2+(G27-G30)^2+(H27-H30)^2+(I27-I30)^2+(J27-J30)^2) -> 0.067788219 | L13: =SQRT((D27-D31)^2+(E27-E31)^2+(F27-F31)^2+(G27-G31)^2+(H27-H31)^2+(I27-I31)^2+(J27-J31)^2) -> 0.049195043 | M13: =L13/(K13+L13) -> 0.42053061 | N13: =RANK(M13,M6:M15,0) -> 6 | O13: ='TAHAP 3 – WP'!M16 -> K2
B14: 9 | C14: ='TAHAP 3 – WP'!C17 -> Indra Kusuma | D14: ='TAHAP 3 – WP'!D17/C16 -> 0.36629484 | E14: ='TAHAP 3 – WP'!E17/D16 -> 0.41208169 | F14: ='TAHAP 3 – WP'!F17/E16 -> 0.36140316 | G14: ='TAHAP 3 – WP'!G17/F16 -> 0.36066785 | H14: ='TAHAP 3 – WP'!H17/G16 -> 0.39970403 | I14: ='TAHAP 3 – WP'!I17/H16 -> 0.41208169 | J14: ='TAHAP 3 – WP'!J17/I16 -> 0.36784039 | K14: =SQRT((D28-D30)^2+(E28-E30)^2+(F28-F30)^2+(G28-G30)^2+(H28-H30)^2+(I28-I30)^2+(J28-J30)^2) -> 0.019976157 | L14: =SQRT((D28-D31)^2+(E28-E31)^2+(F28-F31)^2+(G28-G31)^2+(H28-H31)^2+(I28-I31)^2+(J28-J31)^2) -> 0.09949735 | M14: =L14/(K14+L14) -> 0.83279844 | N14: =RANK(M14,M6:M15,0) -> 3 | O14: ='TAHAP 3 – WP'!M17 -> K1
B15: 10 | C15: ='TAHAP 3 – WP'!C18 -> Joko Purnomo | D15: ='TAHAP 3 – WP'!D18/C16 -> 0.22893427 | E15: ='TAHAP 3 – WP'!E18/D16 -> 0.18314742 | F15: ='TAHAP 3 – WP'!F18/E16 -> 0.22587698 | G15: ='TAHAP 3 – WP'!G18/F16 -> 0.18033393 | H15: ='TAHAP 3 – WP'!H18/G16 -> 0.2220578 | I15: ='TAHAP 3 – WP'!I18/H16 -> 0.18314742 | J15: ='TAHAP 3 – WP'!J18/I16 -> 0.22990024 | K15: =SQRT((D29-D30)^2+(E29-E30)^2+(F29-F30)^2+(G29-G30)^2+(H29-H30)^2+(I29-I30)^2+(J29-J30)^2) -> 0.098599216 | L15: =SQRT((D29-D31)^2+(E29-E31)^2+(F29-F31)^2+(G29-G31)^2+(H29-H31)^2+(I29-I31)^2+(J29-J31)^2) -> 0.020464981 | M15: =L15/(K15+L15) -> 0.1718819 | N15: =RANK(M15,M6:M15,0) -> 9 | O15: ='TAHAP 3 – WP'!M18 -> K3
B16: √(Σxij²) Pembagi | C16: =SQRT(SUMPRODUCT('TAHAP 3 – WP'!D9:D18,'TAHAP 3 – WP'!D9:D18)) -> 21.84033 | D16: =SQRT(SUMPRODUCT('TAHAP 3 – WP'!E9:E18,'TAHAP 3 – WP'!E9:E18)) -> 21.84033 | E16: =SQRT(SUMPRODUCT('TAHAP 3 – WP'!F9:F18,'TAHAP 3 – WP'!F9:F18)) -> 22.135944 | F16: =SQRT(SUMPRODUCT('TAHAP 3 – WP'!G9:G18,'TAHAP 3 – WP'!G9:G18)) -> 22.181073 | G16: =SQRT(SUMPRODUCT('TAHAP 3 – WP'!H9:H18,'TAHAP 3 – WP'!H9:H18)) -> 22.51666 | H16: =SQRT(SUMPRODUCT('TAHAP 3 – WP'!I9:I18,'TAHAP 3 – WP'!I9:I18)) -> 21.84033 | I16: =SQRT(SUMPRODUCT('TAHAP 3 – WP'!J9:J18,'TAHAP 3 – WP'!J9:J18)) -> 21.748563
B18: LANGKAH 2: MATRIKS NORMALISASI TERBOBOT vij = rij × Wj
B19: No | C19: Nama Perawat | D19: v_C1 | E19: v_C2 | F19: v_C3 | G19: v_C4 | H19: v_C5 | I19: v_C6 | J19: v_C7
B20: 1 | C20: =C6 -> Andi Setiawan | D20: =D6*'TAHAP 3 – WP'!C6 -> 0.15315385 | E20: =E6*'TAHAP 3 – WP'!D6 -> 0.073465499 | F20: =F6*'TAHAP 3 – WP'!E6 -> 0.045799407 | G20: =G6*'TAHAP 3 – WP'!F6 -> 0.018346388 | H20: =H6*'TAHAP 3 – WP'!G6 -> 0.04502502 | I20: =I6*'TAHAP 3 – WP'!H6 -> 0.016303543 | J20: =J6*'TAHAP 3 – WP'!I6 -> 0.0094315847
B21: 2 | C21: =C7 -> Budi Santoso | D21: =D7*'TAHAP 3 – WP'!C6 -> 0.095721155 | E21: =E7*'TAHAP 3 – WP'!D6 -> 0.062970428 | F21: =F7*'TAHAP 3 – WP'!E6 -> 0.025444115 | G21: =G7*'TAHAP 3 – WP'!F6 -> 0.013759791 | H21: =H7*'TAHAP 3 – WP'!G6 -> 0.0250139 | I21: =I7*'TAHAP 3 – WP'!H6 -> 0.013974465 | J21: =J7*'TAHAP 3 – WP'!I6 -> 0.0058947404
B22: 3 | C22: =C8 -> Citra Dewi | D22: =D8*'TAHAP 3 – WP'!C6 -> 0.17229808 | E22: =E8*'TAHAP 3 – WP'!D6 -> 0.094455641 | F22: =F8*'TAHAP 3 – WP'!E6 -> 0.040710584 | G22: =G8*'TAHAP 3 – WP'!F6 -> 0.020639686 | H22: =H8*'TAHAP 3 – WP'!G6 -> 0.04502502 | I22: =I8*'TAHAP 3 – WP'!H6 -> 0.01863262 | J22: =J8*'TAHAP 3 – WP'!I6 -> 0.010610533
B23: 4 | C23: =C9 -> Dian Pratiwi | D23: =D9*'TAHAP 3 – WP'!C6 -> 0.11486539 | E23: =E9*'TAHAP 3 – WP'!D6 -> 0.052475356 | F23: =F9*'TAHAP 3 – WP'!E6 -> 0.030532938 | G23: =G9*'TAHAP 3 – WP'!F6 -> 0.011466492 | H23: =H9*'TAHAP 3 – WP'!G6 -> 0.03001668 | I23: =I9*'TAHAP 3 – WP'!H6 -> 0.011645388 | J23: =J9*'TAHAP 3 – WP'!I6 -> 0.0070736885
B24: 5 | C24: =C10 -> Eko Wahyudi | D24: =D10*'TAHAP 3 – WP'!C6 -> 0.13400962 | E24: =E10*'TAHAP 3 – WP'!D6 -> 0.08396057 | F24: =F10*'TAHAP 3 – WP'!E6 -> 0.035621761 | G24: =G10*'TAHAP 3 – WP'!F6 -> 0.018346388 | H24: =H10*'TAHAP 3 – WP'!G6 -> 0.03501946 | I24: =I10*'TAHAP 3 – WP'!H6 -> 0.01863262 | J24: =J10*'TAHAP 3 – WP'!I6 -> 0.0082526366
B25: 6 | C25: =C11 -> Fitri Handayani | D25: =D11*'TAHAP 3 – WP'!C6 -> 0.076576924 | E25: =E11*'TAHAP 3 – WP'!D6 -> 0.052475356 | F25: =F11*'TAHAP 3 – WP'!E6 -> 0.020355292 | G25: =G11*'TAHAP 3 – WP'!F6 -> 0.011466492 | H25: =H11*'TAHAP 3 – WP'!G6 -> 0.02001112 | I25: =I11*'TAHAP 3 – WP'!H6 -> 0.011645388 | J25: =J11*'TAHAP 3 – WP'!I6 -> 0.0047157924
B26: 7 | C26: =C12 -> Galih Nugroho | D26: =D12*'TAHAP 3 – WP'!C6 -> 0.17229808 | E26: =E12*'TAHAP 3 – WP'!D6 -> 0.08396057 | F26: =F12*'TAHAP 3 – WP'!E6 -> 0.045799407 | G26: =G12*'TAHAP 3 – WP'!F6 -> 0.020639686 | H26: =H12*'TAHAP 3 – WP'!G6 -> 0.04002224 | I26: =I12*'TAHAP 3 – WP'!H6 -> 0.020961698 | J26: =J12*'TAHAP 3 – WP'!I6 -> 0.0094315847
B27: 8 | C27: =C13 -> Hana Putri | D27: =D13*'TAHAP 3 – WP'!C6 -> 0.11486539 | E27: =E13*'TAHAP 3 – WP'!D6 -> 0.062970428 | F27: =F13*'TAHAP 3 – WP'!E6 -> 0.035621761 | G27: =G13*'TAHAP 3 – WP'!F6 -> 0.013759791 | H27: =H13*'TAHAP 3 – WP'!G6 -> 0.03501946 | I27: =I13*'TAHAP 3 – WP'!H6 -> 0.013974465 | J27: =J13*'TAHAP 3 – WP'!I6 -> 0.0082526366
B28: 9 | C28: =C14 -> Indra Kusuma | D28: =D14*'TAHAP 3 – WP'!C6 -> 0.15315385 | E28: =E14*'TAHAP 3 – WP'!D6 -> 0.094455641 | F28: =F14*'TAHAP 3 – WP'!E6 -> 0.040710584 | G28: =G14*'TAHAP 3 – WP'!F6 -> 0.018346388 | H28: =H14*'TAHAP 3 – WP'!G6 -> 0.04502502 | I28: =I14*'TAHAP 3 – WP'!H6 -> 0.020961698 | J28: =J14*'TAHAP 3 – WP'!I6 -> 0.0094315847
B29: 10 | C29: =C15 -> Joko Purnomo | D29: =D15*'TAHAP 3 – WP'!C6 -> 0.095721155 | E29: =E15*'TAHAP 3 – WP'!D6 -> 0.041980285 | F29: =F15*'TAHAP 3 – WP'!E6 -> 0.025444115 | G29: =G15*'TAHAP 3 – WP'!F6 -> 0.0091731939 | H29: =H15*'TAHAP 3 – WP'!G6 -> 0.0250139 | I29: =I15*'TAHAP 3 – WP'!H6 -> 0.0093163101 | J29: =J15*'TAHAP 3 – WP'!I6 -> 0.0058947404
B30: A+ (Ideal Positif) | D30: =MAX(D20:D29) -> 0.17229808 | E30: =MAX(E20:E29) -> 0.094455641 | F30: =MAX(F20:F29) -> 0.045799407 | G30: =MAX(G20:G29) -> 0.020639686 | H30: =MAX(H20:H29) -> 0.04502502 | I30: =MAX(I20:I29) -> 0.020961698 | J30: =MAX(J20:J29) -> 0.010610533
B31: A− (Ideal Negatif) | D31: =MIN(D20:D29) -> 0.076576924 | E31: =MIN(E20:E29) -> 0.041980285 | F31: =MIN(F20:F29) -> 0.020355292 | G31: =MIN(G20:G29) -> 0.0091731939 | H31: =MIN(H20:H29) -> 0.02001112 | I31: =MIN(I20:I29) -> 0.0093163101 | J31: =MIN(J20:J29) -> 0.0047157924
B33: VALIDASI KESESUAIAN PERINGKAT WP vs TOPSIS
B34: No | C34: Nama Perawat | D34: Rank WP | E34: Rank TOPSIS | F34: |ΔRank| | G34: Konsisten?
B35: 1 | C35: ='TAHAP 3 – WP'!C9 -> Andi Setiawan | D35: ='TAHAP 3 – WP'!L9 -> 4 | E35: =N6 -> 4 | F35: =ABS(D35-E35) -> 0 | G35: =IF(F35<=1,"✔ YA","✘ TIDAK") -> ✔ YA
B36: 2 | C36: ='TAHAP 3 – WP'!C10 -> Budi Santoso | D36: ='TAHAP 3 – WP'!L10 -> 8 | E36: =N7 -> 8 | F36: =ABS(D36-E36) -> 0 | G36: =IF(F36<=1,"✔ YA","✘ TIDAK") -> ✔ YA
B37: 3 | C37: ='TAHAP 3 – WP'!C11 -> Citra Dewi | D37: ='TAHAP 3 – WP'!L11 -> 1 | E37: =N8 -> 1 | F37: =ABS(D37-E37) -> 0 | G37: =IF(F37<=1,"✔ YA","✘ TIDAK") -> ✔ YA
B38: 4 | C38: ='TAHAP 3 – WP'!C12 -> Dian Pratiwi | D38: ='TAHAP 3 – WP'!L12 -> 7 | E38: =N9 -> 7 | F38: =ABS(D38-E38) -> 0 | G38: =IF(F38<=1,"✔ YA","✘ TIDAK") -> ✔ YA
B39: 5 | C39: ='TAHAP 3 – WP'!C13 -> Eko Wahyudi | D39: ='TAHAP 3 – WP'!L13 -> 5 | E39: =N10 -> 5 | F39: =ABS(D39-E39) -> 0 | G39: =IF(F39<=1,"✔ YA","✘ TIDAK") -> ✔ YA
B40: 6 | C40: ='TAHAP 3 – WP'!C14 -> Fitri Handayani | D40: ='TAHAP 3 – WP'!L14 -> 10 | E40: =N11 -> 10 | F40: =ABS(D40-E40) -> 0 | G40: =IF(F40<=1,"✔ YA","✘ TIDAK") -> ✔ YA
B41: 7 | C41: ='TAHAP 3 – WP'!C15 -> Galih Nugroho | D41: ='TAHAP 3 – WP'!L15 -> 2 | E41: =N12 -> 2 | F41: =ABS(D41-E41) -> 0 | G41: =IF(F41<=1,"✔ YA","✘ TIDAK") -> ✔ YA
B42: 8 | C42: ='TAHAP 3 – WP'!C16 -> Hana Putri | D42: ='TAHAP 3 – WP'!L16 -> 6 | E42: =N13 -> 6 | F42: =ABS(D42-E42) -> 0 | G42: =IF(F42<=1,"✔ YA","✘ TIDAK") -> ✔ YA
B43: 9 | C43: ='TAHAP 3 – WP'!C17 -> Indra Kusuma | D43: ='TAHAP 3 – WP'!L17 -> 3 | E43: =N14 -> 3 | F43: =ABS(D43-E43) -> 0 | G43: =IF(F43<=1,"✔ YA","✘ TIDAK") -> ✔ YA
...

Sheet TAHAP 5 – MODEL
B1: TAHAP 5: MODEL KONSEPTUAL – REKAPITULASI EVALUASI KINERJA PERAWAT
B2: Seluruh data = referensi formula dari sheet sebelumnya | Integrasi K-Means+AHP+WP+TOPSIS
B4: REKAPITULASI FINAL: PEMERINGKATAN KINERJA PERAWAT
B5: No | C5: Nama Perawat | D5: WP Score | E5: Rank WP | F5: TOPSIS Ci | G5: Rank TOPSIS | H5: Klaster | I5: Rank Final (Avg) | J5: Rank Final | K5: Rekomendasi
B6: 1 | C6: ='TAHAP 3 – WP'!C9 -> Andi Setiawan | D6: ='TAHAP 3 – WP'!K9 -> 7.9135552 | E6: ='TAHAP 3 – WP'!L9 -> 4 | F6: ='TAHAP 4 – TOPSIS'!M6 -> 0.75897041 | G6: ='TAHAP 4 – TOPSIS'!N6 -> 4 | H6: ='TAHAP 3 – WP'!M9 -> K1 | I6: =(D6+F6)/2 -> 4.3362628 | J6: =RANK(I6,I6:I15,0) -> 4 | K6: =IF(H6="K1","Promosi / Pengembangan Lanjut",IF(H6="K2","Pertahankan & Tingkatkan","Perlu Pembinaan Intensif")) -> Promosi / Pengembangan Lanjut
B7: 2 | C7: ='TAHAP 3 – WP'!C10 -> Budi Santoso | D7: ='TAHAP 3 – WP'!K10 -> 5.310986 | E7: ='TAHAP 3 – WP'!L10 -> 8 | F7: ='TAHAP 4 – TOPSIS'!M7 -> 0.25391879 | G7: ='TAHAP 4 – TOPSIS'!N7 -> 8 | H7: ='TAHAP 3 – WP'!M10 -> K3 | I7: =(D7+F7)/2 -> 2.7824524 | J7: =RANK(I7,I6:I15,0) -> 8 | K7: =IF(H7="K1","Promosi / Pengembangan Lanjut",IF(H7="K2","Pertahankan & Tingkatkan","Perlu Pembinaan Intensif")) -> Perlu Pembinaan Intensif
B8: 3 | C8: ='TAHAP 3 – WP'!C11 -> Citra Dewi | D8: ='TAHAP 3 – WP'!K11 -> 8.8283262 | E8: ='TAHAP 3 – WP'!L11 -> 1 | F8: ='TAHAP 4 – TOPSIS'!M8 -> 0.95356688 | G8: ='TAHAP 4 – TOPSIS'!N8 -> 1 | H8: ='TAHAP 3 – WP'!M11 -> K1 | I8: =(D8+F8)/2 -> 4.8909465 | J8: =RANK(I8,I6:I15,0) -> 1 | K8: =IF(H8="K1","Promosi / Pengembangan Lanjut",IF(H8="K2","Pertahankan & Tingkatkan","Perlu Pembinaan Intensif")) -> Promosi / Pengembangan Lanjut
B9: 4 | C9: ='TAHAP 3 – WP'!C12 -> Dian Pratiwi | D9: ='TAHAP 3 – WP'!K12 -> 5.6486687 | E9: ='TAHAP 3 – WP'!L12 -> 7 | F9: ='TAHAP 4 – TOPSIS'!M9 -> 0.35947198 | G9: ='TAHAP 4 – TOPSIS'!N9 -> 7 | H9: ='TAHAP 3 – WP'!M12 -> K2 | I9: =(D9+F9)/2 -> 3.0040703 | J9: =RANK(I9,I6:I15,0) -> 7 | K9: =IF(H9="K1","Promosi / Pengembangan Lanjut",IF(H9="K2","Pertahankan & Tingkatkan","Perlu Pembinaan Intensif")) -> Pertahankan & Tingkatkan
B10: 5 | C10: ='TAHAP 3 – WP'!C13 -> Eko Wahyudi | D10: ='TAHAP 3 – WP'!K13 -> 7.3162841 | E10: ='TAHAP 3 – WP'!L13 -> 5 | F10: ='TAHAP 4 – TOPSIS'!M10 -> 0.64052802 | G10: ='TAHAP 4 – TOPSIS'!N10 -> 5 | H10: ='TAHAP 3 – WP'!M13 -> K2 | I10: =(D10+F10)/2 -> 3.978406 | J10: =RANK(I10,I6:I15,0) -> 5 | K10: =IF(H10="K1","Promosi / Pengembangan Lanjut",IF(H10="K2","Pertahankan & Tingkatkan","Perlu Pembinaan Intensif")) -> Pertahankan & Tingkatkan
B11: 6 | C11: ='TAHAP 3 – WP'!C14 -> Fitri Handayani | D11: ='TAHAP 3 – WP'!K14 -> 4.3065798 | E11: ='TAHAP 3 – WP'!L14 -> 10 | F11: ='TAHAP 4 – TOPSIS'!M11 -> 0.089832635 | G11: ='TAHAP 4 – TOPSIS'!N11 -> 10 | H11: ='TAHAP 3 – WP'!M14 -> K3 | I11: =(D11+F11)/2 -> 2.1982062 | J11: =RANK(I11,I6:I15,0) -> 10 | K11: =IF(H11="K1","Promosi / Pengembangan Lanjut",IF(H11="K2","Pertahankan & Tingkatkan","Perlu Pembinaan Intensif")) -> Perlu Pembinaan Intensif
B12: 7 | C12: ='TAHAP 3 – WP'!C15 -> Galih Nugroho | D12: ='TAHAP 3 – WP'!K15 -> 8.6187414 | E12: ='TAHAP 3 – WP'!L15 -> 2 | F12: ='TAHAP 4 – TOPSIS'!M12 -> 0.90454139 | G12: ='TAHAP 4 – TOPSIS'!N12 -> 2 | H12: ='TAHAP 3 – WP'!M15 -> K1 | I12: =(D12+F12)/2 -> 4.7616414 | J12: =RANK(I12,I6:I15,0) -> 2 | K12: =IF(H12="K1","Promosi / Pengembangan Lanjut",IF(H12="K2","Pertahankan & Tingkatkan","Perlu Pembinaan Intensif")) -> Promosi / Pengembangan Lanjut
B13: 8 | C13: ='TAHAP 3 – WP'!C16 -> Hana Putri | D13: ='TAHAP 3 – WP'!K16 -> 6.2366354 | E13: ='TAHAP 3 – WP'!L16 -> 6 | F13: ='TAHAP 4 – TOPSIS'!M13 -> 0.42053061 | G13: ='TAHAP 4 – TOPSIS'!N13 -> 6 | H13: ='TAHAP 3 – WP'!M16 -> K2 | I13: =(D13+F13)/2 -> 3.328583 | J13: =RANK(I13,I6:I15,0) -> 6 | K13: =IF(H13="K1","Promosi / Pengembangan Lanjut",IF(H13="K2","Pertahankan & Tingkatkan","Perlu Pembinaan Intensif")) -> Pertahankan & Tingkatkan
B14: 9 | C14: ='TAHAP 3 – WP'!C17 -> Indra Kusuma | D14: ='TAHAP 3 – WP'!K17 -> 8.3787473 | E14: ='TAHAP 3 – WP'!L17 -> 3 | F14: ='TAHAP 4 – TOPSIS'!M14 -> 0.83279844 | G14: ='TAHAP 4 – TOPSIS'!N14 -> 3 | H14: ='TAHAP 3 – WP'!M17 -> K1 | I14: =(D14+F14)/2 -> 4.6057729 | J14: =RANK(I14,I6:I15,0) -> 3 | K14: =IF(H14="K1","Promosi / Pengembangan Lanjut",IF(H14="K2","Pertahankan & Tingkatkan","Perlu Pembinaan Intensif")) -> Promosi / Pengembangan Lanjut
B15: 10 | C15: ='TAHAP 3 – WP'!C18 -> Joko Purnomo | D15: ='TAHAP 3 – WP'!K18 -> 4.6440565 | E15: ='TAHAP 3 – WP'!L18 -> 9 | F15: ='TAHAP 4 – TOPSIS'!M15 -> 0.1718819 | G15: ='TAHAP 4 – TOPSIS'!N15 -> 9 | H15: ='TAHAP 3 – WP'!M18 -> K3 | I15: =(D15+F15)/2 -> 2.4079692 | J15: =RANK(I15,I6:I15,0) -> 9 | K15: =IF(H15="K1","Promosi / Pengembangan Lanjut",IF(H15="K2","Pertahankan & Tingkatkan","Perlu Pembinaan Intensif")) -> Perlu Pembinaan Intensif
B17: RINGKASAN PER KLASTER (Formula COUNTIF & AVERAGEIF)
B18: Klaster | C18: Jumlah Perawat | D18: Rata-rata WP Score | E18: Rata-rata TOPSIS Ci | F18: Rekomendasi Manajerial
B19: "K1" – Kinerja TINGGI | C19: =COUNTIF(H6:H15,"K1") -> 4 | D19: =AVERAGEIF(H6:H15,"K1",D6:D15) -> 8.4348425 | E19: =AVERAGEIF(H6:H15,"K1",F6:F15) -> 0.86246928 | F19: Prioritas promosi, berikan peran mentor dan pengembangan karir
B20: "K2" – Kinerja SEDANG | C20: =COUNTIF(H6:H15,"K2") -> 3 | D20: =AVERAGEIF(H6:H15,"K2",D6:D15) -> 6.4005294 | E20: =AVERAGEIF(H6:H15,"K2",F6:F15) -> 0.4735102 | F20: Pelatihan targeted, monitoring berkala, reward berbasis capaian
B21: "K3" – Kinerja RENDAH | C21: =COUNTIF(H6:H15,"K3") -> 3 | D21: =AVERAGEIF(H6:H15,"K3",D6:D15) -> 4.7538741 | E21: =AVERAGEIF(H6:H15,"K3",F6:F15) -> 0.17187777 | F21: Program pembinaan intensif, mentoring, review ulang beban kerja
B23: KERANGKA MODEL KONSEPTUAL EVALUASI KINERJA PERAWAT
B24: INPUT | C24: Data kinerja perawat multidimensi (7 kriteria, 10 perawat)
B25: PROSES 1 | C25: K-Means Clustering → Segmentasi klaster kinerja (K1/K2/K3)
B26: PROSES 2 | C26: AHP → Bobot prioritas kriteria, CR < 0.1 (konsisten)
B27: PROSES 3 | C27: Weighted Product (WP) → Skor preferensi Si = ∏(Xij^Wj)
B28: PROSES 4 | C28: TOPSIS → Ci = D− / (D+ + D−), validasi silang ≥ 75%
B29: OUTPUT | C29: Pemeringkatan final + Label klaster kinerja
B30: KEPUTUSAN | C30: Rekomendasi manajerial: Promosi / Pertahankan / Pembinaan Intensif
