Workbook

Sheet COVER
B2: MODEL KONSEPTUAL EVALUASI KINERJA PERAWAT Berbasis Klasterisasi & Hybrid MCDM (AHP–WP–TOPSIS)
B3: Fatkhurrochman, S.Kom, M.Kom | 2026
B5: NAVIGASI SHEET
B6: ▶ TAHAP 1 – K-MEANS | C6: Klasterisasi pola kinerja perawat (K-Means, k=3)
B7: ▶ TAHAP 2 – AHP | C7: Pembobotan kriteria AHP + uji Consistency Ratio
B8: ▶ TAHAP 3 – WP | C8: Agregasi nilai kinerja Weighted Product
B9: ▶ TAHAP 4 – TOPSIS | C9: Validasi pemeringkatan TOPSIS
B10: ▶ TAHAP 5 – MODEL | C10: Rekapitulasi final & Model Konseptual

Sheet TAHAP 1 – K-MEANS
B1: TAHAP 1: KLASTERISASI POLA KINERJA PERAWAT (K-MEANS CLUSTERING)
B2: Algoritma K-Means | 7 Kriteria (C1–C7) | k = 3 Klaster | 10 Perawat | Silhouette Score ≥ 0.5
B4: A. DATA KINERJA PERAWAT (Skala 1–10) — Input Hardcode pada C1–C7
B5: No | C5: Nama Perawat | D5: C1 Komp. Klinis | E5: C2 Profesionalisme | F5: C3 Kolaborasi Tim | G5: C4 Orientasi Hasil | H5: C5 Keselamatan | I5: C6 Mgmt Waktu | J5: C7 Komunikasi | K5: Total Skor | L5: Rata- rata
B6: 1 | C6: Andi Setiawan | D6: 8 | E6: 7 | F6: 9 | G6: 8 | H6: 9 | I6: 7 | J6: 8 | K6: =SUM(D6:J6) -> 56 | L6: =AVERAGE(D6:J6) -> 8 | M6: =J60 -> K1
B7: 2 | C7: Budi Santoso | D7: 5 | E7: 6 | F7: 5 | G7: 6 | H7: 5 | I7: 6 | J7: 5 | K7: =SUM(D7:J7) -> 38 | L7: =AVERAGE(D7:J7) -> 5.4285714 | M7: =J61 -> K3
B8: 3 | C8: Citra Dewi | D8: 9 | E8: 9 | F8: 8 | G8: 9 | H8: 9 | I8: 8 | J8: 9 | K8: =SUM(D8:J8) -> 61 | L8: =AVERAGE(D8:J8) -> 8.7142857 | M8: =J62 -> K1
B9: 4 | C9: Dian Pratiwi | D9: 6 | E9: 5 | F9: 6 | G9: 5 | H9: 6 | I9: 5 | J9: 6 | K9: =SUM(D9:J9) -> 39 | L9: =AVERAGE(D9:J9) -> 5.5714286 | M9: =J63 -> K3
B10: 5 | C10: Eko Wahyudi | D10: 7 | E10: 8 | F10: 7 | G10: 8 | H10: 7 | I10: 8 | J10: 7 | K10: =SUM(D10:J10) -> 52 | L10: =AVERAGE(D10:J10) -> 7.4285714 | M10: =J64 -> K2
B11: 6 | C11: Fitri Handayani | D11: 4 | E11: 5 | F11: 4 | G11: 5 | H11: 4 | I11: 5 | J11: 4 | K11: =SUM(D11:J11) -> 31 | L11: =AVERAGE(D11:J11) -> 4.4285714 | M11: =J65 -> K3
B12: 7 | C12: Galih Nugroho | D12: 9 | E12: 8 | F12: 9 | G12: 9 | H12: 8 | I12: 9 | J12: 8 | K12: =SUM(D12:J12) -> 60 | L12: =AVERAGE(D12:J12) -> 8.5714286 | M12: =J66 -> K1
B13: 8 | C13: Hana Putri | D13: 6 | E13: 6 | F13: 7 | G13: 6 | H13: 7 | I13: 6 | J13: 7 | K13: =SUM(D13:J13) -> 45 | L13: =AVERAGE(D13:J13) -> 6.4285714 | M13: =J67 -> K2
B14: 9 | C14: Indra Kusuma | D14: 8 | E14: 9 | F14: 8 | G14: 8 | H14: 9 | I14: 9 | J14: 8 | K14: =SUM(D14:J14) -> 59 | L14: =AVERAGE(D14:J14) -> 8.4285714 | M14: =J68 -> K1
B15: 10 | C15: Joko Purnomo | D15: 5 | E15: 4 | F15: 5 | G15: 4 | H15: 5 | I15: 4 | J15: 5 | K15: =SUM(D15:J15) -> 32 | L15: =AVERAGE(D15:J15) -> 4.5714286 | M15: =J69 -> K3
B17: B. INISIALISASI CENTROID (Iterasi-0) — Dipilih dari Data (Metode: Random Seed)
B18: Klaster (Seed) | C18: C1 | D18: C2 | E18: C3 | F18: C4 | G18: C5 | H18: C6 | I18: C7 | J18: Sumber Seed | K18: Keterangan
B19: K1 (seed) | C19: 9 | D19: 9 | E19: 8 | F19: 9 | G19: 9 | H19: 8 | I19: 9 | J19: Citra Dewi (baris 3) | K19: Performa tinggi sebagai centroid awal K1
B20: K2 (seed) | C20: 7 | D20: 8 | E20: 7 | F20: 8 | G20: 7 | H20: 8 | I20: 7 | J20: Eko Wahyudi (baris 5) | K20: Performa sedang sebagai centroid awal K2
B21: K3 (seed) | C21: 4 | D21: 5 | E21: 4 | F21: 5 | G21: 4 | H21: 5 | I21: 4 | J21: Fitri Handayani (baris 6) | K21: Performa rendah sebagai centroid awal K3
B23: C. PROSES ITERASI K-MEANS — Seluruh Iterasi Ditampilkan hingga Konvergen
B24: ITERASI 1 — Penugasan Klaster (menggunakan Centroid Inisialisasi / Seed)
B25: No | C25: Nama Perawat | D25: d²→K1 | E25: d²→K2 | F25: d²→K3 | G25: D→K1 | H25: D→K2 | I25: D→K3 | J25: Klaster Terdekat | K25: Keterangan
B26: 1 | C26: =C6 -> Andi Setiawan | D26: =(D6-C19)^2+(E6-D19)^2+(F6-E19)^2+(G6-F19)^2+(H6-G19)^2+(I6-H19)^2+(J6-I19)^2 -> 9 | E26: =(D6-C20)^2+(E6-D20)^2+(F6-E20)^2+(G6-F20)^2+(H6-G20)^2+(I6-H20)^2+(J6-I20)^2 -> 12 | F26: =(D6-C21)^2+(E6-D21)^2+(F6-E21)^2+(G6-F21)^2+(H6-G21)^2+(I6-H21)^2+(J6-I21)^2 -> 99 | G26: =SQRT(D26) -> 3 | H26: =SQRT(E26) -> 3.4641016 | I26: =SQRT(F26) -> 9.9498744 | J26: =IF(AND(G26<=H26,G26<=I26),"K1",IF(H26<=I26,"K2","K3")) -> K1 | K26: =IF(J26="K1","Dekat K1 (Tinggi)",IF(J26="K2","Dekat K2 (Sedang)","Dekat K3 (Rendah)")) -> Dekat K1 (Tinggi)
B27: 2 | C27: =C7 -> Budi Santoso | D27: =(D7-C19)^2+(E7-D19)^2+(F7-E19)^2+(G7-F19)^2+(H7-G19)^2+(I7-H19)^2+(J7-I19)^2 -> 79 | E27: =(D7-C20)^2+(E7-D20)^2+(F7-E20)^2+(G7-F20)^2+(H7-G20)^2+(I7-H20)^2+(J7-I20)^2 -> 28 | F27: =(D7-C21)^2+(E7-D21)^2+(F7-E21)^2+(G7-F21)^2+(H7-G21)^2+(I7-H21)^2+(J7-I21)^2 -> 7 | G27: =SQRT(D27) -> 8.8881944 | H27: =SQRT(E27) -> 5.2915026 | I27: =SQRT(F27) -> 2.6457513 | J27: =IF(AND(G27<=H27,G27<=I27),"K1",IF(H27<=I27,"K2","K3")) -> K3 | K27: =IF(J27="K1","Dekat K1 (Tinggi)",IF(J27="K2","Dekat K2 (Sedang)","Dekat K3 (Rendah)")) -> Dekat K3 (Rendah)
B28: 3 | C28: =C8 -> Citra Dewi | D28: =(D8-C19)^2+(E8-D19)^2+(F8-E19)^2+(G8-F19)^2+(H8-G19)^2+(I8-H19)^2+(J8-I19)^2 -> 0 | E28: =(D8-C20)^2+(E8-D20)^2+(F8-E20)^2+(G8-F20)^2+(H8-G20)^2+(I8-H20)^2+(J8-I20)^2 -> 15 | F28: =(D8-C21)^2+(E8-D21)^2+(F8-E21)^2+(G8-F21)^2+(H8-G21)^2+(I8-H21)^2+(J8-I21)^2 -> 132 | G28: =SQRT(D28) -> 0 | H28: =SQRT(E28) -> 3.8729833 | I28: =SQRT(F28) -> 11.489125 | J28: =IF(AND(G28<=H28,G28<=I28),"K1",IF(H28<=I28,"K2","K3")) -> K1 | K28: =IF(J28="K1","Dekat K1 (Tinggi)",IF(J28="K2","Dekat K2 (Sedang)","Dekat K3 (Rendah)")) -> Dekat K1 (Tinggi)
B29: 4 | C29: =C9 -> Dian Pratiwi | D29: =(D9-C19)^2+(E9-D19)^2+(F9-E19)^2+(G9-F19)^2+(H9-G19)^2+(I9-H19)^2+(J9-I19)^2 -> 72 | E29: =(D9-C20)^2+(E9-D20)^2+(F9-E20)^2+(G9-F20)^2+(H9-G20)^2+(I9-H20)^2+(J9-I20)^2 -> 31 | F29: =(D9-C21)^2+(E9-D21)^2+(F9-E21)^2+(G9-F21)^2+(H9-G21)^2+(I9-H21)^2+(J9-I21)^2 -> 16 | G29: =SQRT(D29) -> 8.4852814 | H29: =SQRT(E29) -> 5.5677644 | I29: =SQRT(F29) -> 4 | J29: =IF(AND(G29<=H29,G29<=I29),"K1",IF(H29<=I29,"K2","K3")) -> K3 | K29: =IF(J29="K1","Dekat K1 (Tinggi)",IF(J29="K2","Dekat K2 (Sedang)","Dekat K3 (Rendah)")) -> Dekat K3 (Rendah)
B30: 5 | C30: =C10 -> Eko Wahyudi | D30: =(D10-C19)^2+(E10-D19)^2+(F10-E19)^2+(G10-F19)^2+(H10-G19)^2+(I10-H19)^2+(J10-I19)^2 -> 15 | E30: =(D10-C20)^2+(E10-D20)^2+(F10-E20)^2+(G10-F20)^2+(H10-G20)^2+(I10-H20)^2+(J10-I20)^2 -> 0 | F30: =(D10-C21)^2+(E10-D21)^2+(F10-E21)^2+(G10-F21)^2+(H10-G21)^2+(I10-H21)^2+(J10-I21)^2 -> 63 | G30: =SQRT(D30) -> 3.8729833 | H30: =SQRT(E30) -> 0 | I30: =SQRT(F30) -> 7.9372539 | J30: =IF(AND(G30<=H30,G30<=I30),"K1",IF(H30<=I30,"K2","K3")) -> K2 | K30: =IF(J30="K1","Dekat K1 (Tinggi)",IF(J30="K2","Dekat K2 (Sedang)","Dekat K3 (Rendah)")) -> Dekat K2 (Sedang)
B31: 6 | C31: =C11 -> Fitri Handayani | D31: =(D11-C19)^2+(E11-D19)^2+(F11-E19)^2+(G11-F19)^2+(H11-G19)^2+(I11-H19)^2+(J11-I19)^2 -> 132 | E31: =(D11-C20)^2+(E11-D20)^2+(F11-E20)^2+(G11-F20)^2+(H11-G20)^2+(I11-H20)^2+(J11-I20)^2 -> 63 | F31: =(D11-C21)^2+(E11-D21)^2+(F11-E21)^2+(G11-F21)^2+(H11-G21)^2+(I11-H21)^2+(J11-I21)^2 -> 0 | G31: =SQRT(D31) -> 11.489125 | H31: =SQRT(E31) -> 7.9372539 | I31: =SQRT(F31) -> 0 | J31: =IF(AND(G31<=H31,G31<=I31),"K1",IF(H31<=I31,"K2","K3")) -> K3 | K31: =IF(J31="K1","Dekat K1 (Tinggi)",IF(J31="K2","Dekat K2 (Sedang)","Dekat K3 (Rendah)")) -> Dekat K3 (Rendah)
B32: 7 | C32: =C12 -> Galih Nugroho | D32: =(D12-C19)^2+(E12-D19)^2+(F12-E19)^2+(G12-F19)^2+(H12-G19)^2+(I12-H19)^2+(J12-I19)^2 -> 5 | E32: =(D12-C20)^2+(E12-D20)^2+(F12-E20)^2+(G12-F20)^2+(H12-G20)^2+(I12-H20)^2+(J12-I20)^2 -> 12 | F32: =(D12-C21)^2+(E12-D21)^2+(F12-E21)^2+(G12-F21)^2+(H12-G21)^2+(I12-H21)^2+(J12-I21)^2 -> 123 | G32: =SQRT(D32) -> 2.236068 | H32: =SQRT(E32) -> 3.4641016 | I32: =SQRT(F32) -> 11.090537 | J32: =IF(AND(G32<=H32,G32<=I32),"K1",IF(H32<=I32,"K2","K3")) -> K1 | K32: =IF(J32="K1","Dekat K1 (Tinggi)",IF(J32="K2","Dekat K2 (Sedang)","Dekat K3 (Rendah)")) -> Dekat K1 (Tinggi)
B33: 8 | C33: =C13 -> Hana Putri | D33: =(D13-C19)^2+(E13-D19)^2+(F13-E19)^2+(G13-F19)^2+(H13-G19)^2+(I13-H19)^2+(J13-I19)^2 -> 40 | E33: =(D13-C20)^2+(E13-D20)^2+(F13-E20)^2+(G13-F20)^2+(H13-G20)^2+(I13-H20)^2+(J13-I20)^2 -> 13 | F33: =(D13-C21)^2+(E13-D21)^2+(F13-E21)^2+(G13-F21)^2+(H13-G21)^2+(I13-H21)^2+(J13-I21)^2 -> 34 | G33: =SQRT(D33) -> 6.3245553 | H33: =SQRT(E33) -> 3.6055513 | I33: =SQRT(F33) -> 5.8309519 | J33: =IF(AND(G33<=H33,G33<=I33),"K1",IF(H33<=I33,"K2","K3")) -> K2 | K33: =IF(J33="K1","Dekat K1 (Tinggi)",IF(J33="K2","Dekat K2 (Sedang)","Dekat K3 (Rendah)")) -> Dekat K2 (Sedang)
B34: 9 | C34: =C14 -> Indra Kusuma | D34: =(D14-C19)^2+(E14-D19)^2+(F14-E19)^2+(G14-F19)^2+(H14-G19)^2+(I14-H19)^2+(J14-I19)^2 -> 4 | E34: =(D14-C20)^2+(E14-D20)^2+(F14-E20)^2+(G14-F20)^2+(H14-G20)^2+(I14-H20)^2+(J14-I20)^2 -> 9 | F34: =(D14-C21)^2+(E14-D21)^2+(F14-E21)^2+(G14-F21)^2+(H14-G21)^2+(I14-H21)^2+(J14-I21)^2 -> 114 | G34: =SQRT(D34) -> 2 | H34: =SQRT(E34) -> 3 | I34: =SQRT(F34) -> 10.677078 | J34: =IF(AND(G34<=H34,G34<=I34),"K1",IF(H34<=I34,"K2","K3")) -> K1 | K34: =IF(J34="K1","Dekat K1 (Tinggi)",IF(J34="K2","Dekat K2 (Sedang)","Dekat K3 (Rendah)")) -> Dekat K1 (Tinggi)
B35: 10 | C35: =C15 -> Joko Purnomo | D35: =(D15-C19)^2+(E15-D19)^2+(F15-E19)^2+(G15-F19)^2+(H15-G19)^2+(I15-H19)^2+(J15-I19)^2 -> 123 | E35: =(D15-C20)^2+(E15-D20)^2+(F15-E20)^2+(G15-F20)^2+(H15-G20)^2+(I15-H20)^2+(J15-I20)^2 -> 64 | F35: =(D15-C21)^2+(E15-D21)^2+(F15-E21)^2+(G15-F21)^2+(H15-G21)^2+(I15-H21)^2+(J15-I21)^2 -> 7 | G35: =SQRT(D35) -> 11.090537 | H35: =SQRT(E35) -> 8 | I35: =SQRT(F35) -> 2.6457513 | J35: =IF(AND(G35<=H35,G35<=I35),"K1",IF(H35<=I35,"K2","K3")) -> K3 | K35: =IF(J35="K1","Dekat K1 (Tinggi)",IF(J35="K2","Dekat K2 (Sedang)","Dekat K3 (Rendah)")) -> Dekat K3 (Rendah)
B36: UPDATE CENTROID — Setelah Iterasi 1 (Centroid baru = rata-rata nilai anggota klaster)
B37: Klaster | C37: C1 | D37: C2 | E37: C3 | F37: C4 | G37: C5 | H37: C6 | I37: C7 | J37: Anggota (n) | K37: Formula Rata-rata
B38: K1 | C38: =IFERROR(AVERAGEIF(J26:J35,"K1",D6:D15),0) -> 8.5 | D38: =IFERROR(AVERAGEIF(J26:J35,"K1",E6:E15),0) -> 8.25 | E38: =IFERROR(AVERAGEIF(J26:J35,"K1",F6:F15),0) -> 8.5 | F38: =IFERROR(AVERAGEIF(J26:J35,"K1",G6:G15),0) -> 8.5 | G38: =IFERROR(AVERAGEIF(J26:J35,"K1",H6:H15),0) -> 8.75 | H38: =IFERROR(AVERAGEIF(J26:J35,"K1",I6:I15),0) -> 8.25 | I38: =IFERROR(AVERAGEIF(J26:J35,"K1",J6:J15),0) -> 8.25 | J38: =COUNTIF(J26:J35,"K1") -> 4 | K38: Rata-rata C1..C7 anggota K1
B39: K2 | C39: =IFERROR(AVERAGEIF(J26:J35,"K2",D6:D15),0) -> 6.5 | D39: =IFERROR(AVERAGEIF(J26:J35,"K2",E6:E15),0) -> 7 | E39: =IFERROR(AVERAGEIF(J26:J35,"K2",F6:F15),0) -> 7 | F39: =IFERROR(AVERAGEIF(J26:J35,"K2",G6:G15),0) -> 7 | G39: =IFERROR(AVERAGEIF(J26:J35,"K2",H6:H15),0) -> 7 | H39: =IFERROR(AVERAGEIF(J26:J35,"K2",I6:I15),0) -> 7 | I39: =IFERROR(AVERAGEIF(J26:J35,"K2",J6:J15),0) -> 7 | J39: =COUNTIF(J26:J35,"K2") -> 2 | K39: Rata-rata C1..C7 anggota K2
B40: K3 | C40: =IFERROR(AVERAGEIF(J26:J35,"K3",D6:D15),0) -> 5 | D40: =IFERROR(AVERAGEIF(J26:J35,"K3",E6:E15),0) -> 5 | E40: =IFERROR(AVERAGEIF(J26:J35,"K3",F6:F15),0) -> 5 | F40: =IFERROR(AVERAGEIF(J26:J35,"K3",G6:G15),0) -> 5 | G40: =IFERROR(AVERAGEIF(J26:J35,"K3",H6:H15),0) -> 5 | H40: =IFERROR(AVERAGEIF(J26:J35,"K3",I6:I15),0) -> 5 | I40: =IFERROR(AVERAGEIF(J26:J35,"K3",J6:J15),0) -> 5 | J40: =COUNTIF(J26:J35,"K3") -> 4 | K40: Rata-rata C1..C7 anggota K3
B41: ITERASI 2 — Penugasan Klaster (menggunakan Centroid Update dari Iterasi 1)
B42: No | C42: Nama Perawat | D42: d²→K1 | E42: d²→K2 | F42: d²→K3 | G42: D→K1 | H42: D→K2 | I42: D→K3 | J42: Klaster Terdekat | K42: Keterangan
B43: 1 | C43: =C6 -> Andi Setiawan | D43: =(D6-C38)^2+(E6-D38)^2+(F6-E38)^2+(G6-F38)^2+(H6-G38)^2+(I6-H38)^2+(J6-I38)^2 -> 4 | E43: =(D6-C39)^2+(E6-D39)^2+(F6-E39)^2+(G6-F39)^2+(H6-G39)^2+(I6-H39)^2+(J6-I39)^2 -> 12.25 | F43: =(D6-C40)^2+(E6-D40)^2+(F6-E40)^2+(G6-F40)^2+(H6-G40)^2+(I6-H40)^2+(J6-I40)^2 -> 67 | G43: =SQRT(D43) -> 2 | H43: =SQRT(E43) -> 3.5 | I43: =SQRT(F43) -> 8.1853528 | J43: =IF(AND(G43<=H43,G43<=I43),"K1",IF(H43<=I43,"K2","K3")) -> K1 | K43: =IF(J43="K1","Dekat K1 (Tinggi)",IF(J43="K2","Dekat K2 (Sedang)","Dekat K3 (Rendah)")) -> Dekat K1 (Tinggi)
...

Sheet SILHOUETTE
B1: TAHAP 1D: PERHITUNGAN SILHOUETTE SCORE — VALIDASI KLASTERISASI K-MEANS
B2: s(i) = (b(i) − a(i)) / max(a(i), b(i)) | S = (1/n)×Σs(i) | a(i) = avg jarak ke sesama klaster | b(i) = avg jarak ke klaster terdekat lainnya
B4: A. DATA KINERJA & KLASTER FINAL (referensi dari 'TAHAP 1 – K-MEANS')
B5: No | C5: Nama Perawat | D5: C1 | E5: C2 | F5: C3 | G5: C4 | H5: C5 | I5: C6 | J5: C7 | K5: Klaster
B6: ='TAHAP 1 – K-MEANS'!B6 -> 1 | C6: ='TAHAP 1 – K-MEANS'!C6 -> Andi Setiawan | D6: ='TAHAP 1 – K-MEANS'!D6 -> 8 | E6: ='TAHAP 1 – K-MEANS'!E6 -> 7 | F6: ='TAHAP 1 – K-MEANS'!F6 -> 9 | G6: ='TAHAP 1 – K-MEANS'!G6 -> 8 | H6: ='TAHAP 1 – K-MEANS'!H6 -> 9 | I6: ='TAHAP 1 – K-MEANS'!I6 -> 7 | J6: ='TAHAP 1 – K-MEANS'!J6 -> 8 | K6: ='TAHAP 1 – K-MEANS'!M80 -> K1
B7: ='TAHAP 1 – K-MEANS'!B7 -> 2 | C7: ='TAHAP 1 – K-MEANS'!C7 -> Budi Santoso | D7: ='TAHAP 1 – K-MEANS'!D7 -> 5 | E7: ='TAHAP 1 – K-MEANS'!E7 -> 6 | F7: ='TAHAP 1 – K-MEANS'!F7 -> 5 | G7: ='TAHAP 1 – K-MEANS'!G7 -> 6 | H7: ='TAHAP 1 – K-MEANS'!H7 -> 5 | I7: ='TAHAP 1 – K-MEANS'!I7 -> 6 | J7: ='TAHAP 1 – K-MEANS'!J7 -> 5 | K7: ='TAHAP 1 – K-MEANS'!M81 -> K3
B8: ='TAHAP 1 – K-MEANS'!B8 -> 3 | C8: ='TAHAP 1 – K-MEANS'!C8 -> Citra Dewi | D8: ='TAHAP 1 – K-MEANS'!D8 -> 9 | E8: ='TAHAP 1 – K-MEANS'!E8 -> 9 | F8: ='TAHAP 1 – K-MEANS'!F8 -> 8 | G8: ='TAHAP 1 – K-MEANS'!G8 -> 9 | H8: ='TAHAP 1 – K-MEANS'!H8 -> 9 | I8: ='TAHAP 1 – K-MEANS'!I8 -> 8 | J8: ='TAHAP 1 – K-MEANS'!J8 -> 9 | K8: ='TAHAP 1 – K-MEANS'!M82 -> K1
B9: ='TAHAP 1 – K-MEANS'!B9 -> 4 | C9: ='TAHAP 1 – K-MEANS'!C9 -> Dian Pratiwi | D9: ='TAHAP 1 – K-MEANS'!D9 -> 6 | E9: ='TAHAP 1 – K-MEANS'!E9 -> 5 | F9: ='TAHAP 1 – K-MEANS'!F9 -> 6 | G9: ='TAHAP 1 – K-MEANS'!G9 -> 5 | H9: ='TAHAP 1 – K-MEANS'!H9 -> 6 | I9: ='TAHAP 1 – K-MEANS'!I9 -> 5 | J9: ='TAHAP 1 – K-MEANS'!J9 -> 6 | K9: ='TAHAP 1 – K-MEANS'!M83 -> K3
B10: ='TAHAP 1 – K-MEANS'!B10 -> 5 | C10: ='TAHAP 1 – K-MEANS'!C10 -> Eko Wahyudi | D10: ='TAHAP 1 – K-MEANS'!D10 -> 7 | E10: ='TAHAP 1 – K-MEANS'!E10 -> 8 | F10: ='TAHAP 1 – K-MEANS'!F10 -> 7 | G10: ='TAHAP 1 – K-MEANS'!G10 -> 8 | H10: ='TAHAP 1 – K-MEANS'!H10 -> 7 | I10: ='TAHAP 1 – K-MEANS'!I10 -> 8 | J10: ='TAHAP 1 – K-MEANS'!J10 -> 7 | K10: ='TAHAP 1 – K-MEANS'!M84 -> K2
B11: ='TAHAP 1 – K-MEANS'!B11 -> 6 | C11: ='TAHAP 1 – K-MEANS'!C11 -> Fitri Handayani | D11: ='TAHAP 1 – K-MEANS'!D11 -> 4 | E11: ='TAHAP 1 – K-MEANS'!E11 -> 5 | F11: ='TAHAP 1 – K-MEANS'!F11 -> 4 | G11: ='TAHAP 1 – K-MEANS'!G11 -> 5 | H11: ='TAHAP 1 – K-MEANS'!H11 -> 4 | I11: ='TAHAP 1 – K-MEANS'!I11 -> 5 | J11: ='TAHAP 1 – K-MEANS'!J11 -> 4 | K11: ='TAHAP 1 – K-MEANS'!M85 -> K3
B12: ='TAHAP 1 – K-MEANS'!B12 -> 7 | C12: ='TAHAP 1 – K-MEANS'!C12 -> Galih Nugroho | D12: ='TAHAP 1 – K-MEANS'!D12 -> 9 | E12: ='TAHAP 1 – K-MEANS'!E12 -> 8 | F12: ='TAHAP 1 – K-MEANS'!F12 -> 9 | G12: ='TAHAP 1 – K-MEANS'!G12 -> 9 | H12: ='TAHAP 1 – K-MEANS'!H12 -> 8 | I12: ='TAHAP 1 – K-MEANS'!I12 -> 9 | J12: ='TAHAP 1 – K-MEANS'!J12 -> 8 | K12: ='TAHAP 1 – K-MEANS'!M86 -> K1
B13: ='TAHAP 1 – K-MEANS'!B13 -> 8 | C13: ='TAHAP 1 – K-MEANS'!C13 -> Hana Putri | D13: ='TAHAP 1 – K-MEANS'!D13 -> 6 | E13: ='TAHAP 1 – K-MEANS'!E13 -> 6 | F13: ='TAHAP 1 – K-MEANS'!F13 -> 7 | G13: ='TAHAP 1 – K-MEANS'!G13 -> 6 | H13: ='TAHAP 1 – K-MEANS'!H13 -> 7 | I13: ='TAHAP 1 – K-MEANS'!I13 -> 6 | J13: ='TAHAP 1 – K-MEANS'!J13 -> 7 | K13: ='TAHAP 1 – K-MEANS'!M87 -> K2
B14: ='TAHAP 1 – K-MEANS'!B14 -> 9 | C14: ='TAHAP 1 – K-MEANS'!C14 -> Indra Kusuma | D14: ='TAHAP 1 – K-MEANS'!D14 -> 8 | E14: ='TAHAP 1 – K-MEANS'!E14 -> 9 | F14: ='TAHAP 1 – K-MEANS'!F14 -> 8 | G14: ='TAHAP 1 – K-MEANS'!G14 -> 8 | H14: ='TAHAP 1 – K-MEANS'!H14 -> 9 | I14: ='TAHAP 1 – K-MEANS'!I14 -> 9 | J14: ='TAHAP 1 – K-MEANS'!J14 -> 8 | K14: ='TAHAP 1 – K-MEANS'!M88 -> K1
B15: ='TAHAP 1 – K-MEANS'!B15 -> 10 | C15: ='TAHAP 1 – K-MEANS'!C15 -> Joko Purnomo | D15: ='TAHAP 1 – K-MEANS'!D15 -> 5 | E15: ='TAHAP 1 – K-MEANS'!E15 -> 4 | F15: ='TAHAP 1 – K-MEANS'!F15 -> 5 | G15: ='TAHAP 1 – K-MEANS'!G15 -> 4 | H15: ='TAHAP 1 – K-MEANS'!H15 -> 5 | I15: ='TAHAP 1 – K-MEANS'!I15 -> 4 | J15: ='TAHAP 1 – K-MEANS'!J15 -> 5 | K15: ='TAHAP 1 – K-MEANS'!M89 -> K3
M18: B. MATRIKS JARAK EUCLIDEAN dij = SQRT(Σ(Ck_i − Ck_j)²) — diagonal = 0
M19: Perawat | N19: Nama | O19: P1 | P19: P2 | Q19: P3 | R19: P4 | S19: P5 | T19: P6 | U19: P7 | V19: P8 | W19: P9 | X19: P10
M20: =B6 -> 1 | N20: =C6 -> Andi Setiawan | O20: 0 | P20: =SQRT((D6-D7)^2+(E6-E7)^2+(F6-F7)^2+(G6-G7)^2+(H6-H7)^2+(I6-I7)^2+(J6-J7)^2) -> 7.4833148 | Q20: =SQRT((D6-D8)^2+(E6-E8)^2+(F6-F8)^2+(G6-G8)^2+(H6-H8)^2+(I6-I8)^2+(J6-J8)^2) -> 3 | R20: =SQRT((D6-D9)^2+(E6-E9)^2+(F6-F9)^2+(G6-G9)^2+(H6-H9)^2+(I6-I9)^2+(J6-J9)^2) -> 6.5574385 | S20: =SQRT((D6-D10)^2+(E6-E10)^2+(F6-F10)^2+(G6-G10)^2+(H6-H10)^2+(I6-I10)^2+(J6-J10)^2) -> 3.4641016 | T20: =SQRT((D6-D11)^2+(E6-E11)^2+(F6-F11)^2+(G6-G11)^2+(H6-H11)^2+(I6-I11)^2+(J6-J11)^2) -> 9.9498744 | U20: =SQRT((D6-D12)^2+(E6-E12)^2+(F6-F12)^2+(G6-G12)^2+(H6-H12)^2+(I6-I12)^2+(J6-J12)^2) -> 2.8284271 | V20: =SQRT((D6-D13)^2+(E6-E13)^2+(F6-F13)^2+(G6-G13)^2+(H6-H13)^2+(I6-I13)^2+(J6-J13)^2) -> 4.3588989 | W20: =SQRT((D6-D14)^2+(E6-E14)^2+(F6-F14)^2+(G6-G14)^2+(H6-H14)^2+(I6-I14)^2+(J6-J14)^2) -> 3 | X20: =SQRT((D6-D15)^2+(E6-E15)^2+(F6-F15)^2+(G6-G15)^2+(H6-H15)^2+(I6-I15)^2+(J6-J15)^2) -> 9.1651514
M21: =B7 -> 2 | N21: =C7 -> Budi Santoso | O21: =SQRT((D7-D6)^2+(E7-E6)^2+(F7-F6)^2+(G7-G6)^2+(H7-H6)^2+(I7-I6)^2+(J7-J6)^2) -> 7.4833148 | P21: 0 | Q21: =SQRT((D7-D8)^2+(E7-E8)^2+(F7-F8)^2+(G7-G8)^2+(H7-H8)^2+(I7-I8)^2+(J7-J8)^2) -> 8.8881944 | R21: =SQRT((D7-D9)^2+(E7-E9)^2+(F7-F9)^2+(G7-G9)^2+(H7-H9)^2+(I7-I9)^2+(J7-J9)^2) -> 2.6457513 | S21: =SQRT((D7-D10)^2+(E7-E10)^2+(F7-F10)^2+(G7-G10)^2+(H7-H10)^2+(I7-I10)^2+(J7-J10)^2) -> 5.2915026 | T21: =SQRT((D7-D11)^2+(E7-E11)^2+(F7-F11)^2+(G7-G11)^2+(H7-H11)^2+(I7-I11)^2+(J7-J11)^2) -> 2.6457513 | U21: =SQRT((D7-D12)^2+(E7-E12)^2+(F7-F12)^2+(G7-G12)^2+(H7-H12)^2+(I7-I12)^2+(J7-J12)^2) -> 8.4852814 | V21: =SQRT((D7-D13)^2+(E7-E13)^2+(F7-F13)^2+(G7-G13)^2+(H7-H13)^2+(I7-I13)^2+(J7-J13)^2) -> 3.6055513 | W21: =SQRT((D7-D14)^2+(E7-E14)^2+(F7-F14)^2+(G7-G14)^2+(H7-H14)^2+(I7-I14)^2+(J7-J14)^2) -> 8.0622577 | X21: =SQRT((D7-D15)^2+(E7-E15)^2+(F7-F15)^2+(G7-G15)^2+(H7-H15)^2+(I7-I15)^2+(J7-J15)^2) -> 3.4641016
M22: =B8 -> 3 | N22: =C8 -> Citra Dewi | O22: =SQRT((D8-D6)^2+(E8-E6)^2+(F8-F6)^2+(G8-G6)^2+(H8-H6)^2+(I8-I6)^2+(J8-J6)^2) -> 3 | P22: =SQRT((D8-D7)^2+(E8-E7)^2+(F8-F7)^2+(G8-G7)^2+(H8-H7)^2+(I8-I7)^2+(J8-J7)^2) -> 8.8881944 | Q22: 0 | R22: =SQRT((D8-D9)^2+(E8-E9)^2+(F8-F9)^2+(G8-G9)^2+(H8-H9)^2+(I8-I9)^2+(J8-J9)^2) -> 8.4852814 | S22: =SQRT((D8-D10)^2+(E8-E10)^2+(F8-F10)^2+(G8-G10)^2+(H8-H10)^2+(I8-I10)^2+(J8-J10)^2) -> 3.8729833 | T22: =SQRT((D8-D11)^2+(E8-E11)^2+(F8-F11)^2+(G8-G11)^2+(H8-H11)^2+(I8-I11)^2+(J8-J11)^2) -> 11.489125 | U22: =SQRT((D8-D12)^2+(E8-E12)^2+(F8-F12)^2+(G8-G12)^2+(H8-H12)^2+(I8-I12)^2+(J8-J12)^2) -> 2.236068 | V22: =SQRT((D8-D13)^2+(E8-E13)^2+(F8-F13)^2+(G8-G13)^2+(H8-H13)^2+(I8-I13)^2+(J8-J13)^2) -> 6.3245553 | W22: =SQRT((D8-D14)^2+(E8-E14)^2+(F8-F14)^2+(G8-G14)^2+(H8-H14)^2+(I8-I14)^2+(J8-J14)^2) -> 2 | X22: =SQRT((D8-D15)^2+(E8-E15)^2+(F8-F15)^2+(G8-G15)^2+(H8-H15)^2+(I8-I15)^2+(J8-J15)^2) -> 11.090537
M23: =B9 -> 4 | N23: =C9 -> Dian Pratiwi | O23: =SQRT((D9-D6)^2+(E9-E6)^2+(F9-F6)^2+(G9-G6)^2+(H9-H6)^2+(I9-I6)^2+(J9-J6)^2) -> 6.5574385 | P23: =SQRT((D9-D7)^2+(E9-E7)^2+(F9-F7)^2+(G9-G7)^2+(H9-H7)^2+(I9-I7)^2+(J9-J7)^2) -> 2.6457513 | Q23: =SQRT((D9-D8)^2+(E9-E8)^2+(F9-F8)^2+(G9-G8)^2+(H9-H8)^2+(I9-I8)^2+(J9-J8)^2) -> 8.4852814 | R23: 0 | S23: =SQRT((D9-D10)^2+(E9-E10)^2+(F9-F10)^2+(G9-G10)^2+(H9-H10)^2+(I9-I10)^2+(J9-J10)^2) -> 5.5677644 | T23: =SQRT((D9-D11)^2+(E9-E11)^2+(F9-F11)^2+(G9-G11)^2+(H9-H11)^2+(I9-I11)^2+(J9-J11)^2) -> 4 | U23: =SQRT((D9-D12)^2+(E9-E12)^2+(F9-F12)^2+(G9-G12)^2+(H9-H12)^2+(I9-I12)^2+(J9-J12)^2) -> 8.1853528 | V23: =SQRT((D9-D13)^2+(E9-E13)^2+(F9-F13)^2+(G9-G13)^2+(H9-H13)^2+(I9-I13)^2+(J9-J13)^2) -> 2.4494897 | W23: =SQRT((D9-D14)^2+(E9-E14)^2+(F9-F14)^2+(G9-G14)^2+(H9-H14)^2+(I9-I14)^2+(J9-J14)^2) -> 7.8740079 | X23: =SQRT((D9-D15)^2+(E9-E15)^2+(F9-F15)^2+(G9-G15)^2+(H9-H15)^2+(I9-I15)^2+(J9-J15)^2) -> 2.6457513
M24: =B10 -> 5 | N24: =C10 -> Eko Wahyudi | O24: =SQRT((D10-D6)^2+(E10-E6)^2+(F10-F6)^2+(G10-G6)^2+(H10-H6)^2+(I10-I6)^2+(J10-J6)^2) -> 3.4641016 | P24: =SQRT((D10-D7)^2+(E10-E7)^2+(F10-F7)^2+(G10-G7)^2+(H10-H7)^2+(I10-I7)^2+(J10-J7)^2) -> 5.2915026 | Q24: =SQRT((D10-D8)^2+(E10-E8)^2+(F10-F8)^2+(G10-G8)^2+(H10-H8)^2+(I10-I8)^2+(J10-J8)^2) -> 3.8729833 | R24: =SQRT((D10-D9)^2+(E10-E9)^2+(F10-F9)^2+(G10-G9)^2+(H10-H9)^2+(I10-I9)^2+(J10-J9)^2) -> 5.5677644 | S24: 0 | T24: =SQRT((D10-D11)^2+(E10-E11)^2+(F10-F11)^2+(G10-G11)^2+(H10-H11)^2+(I10-I11)^2+(J10-J11)^2) -> 7.9372539 | U24: =SQRT((D10-D12)^2+(E10-E12)^2+(F10-F12)^2+(G10-G12)^2+(H10-H12)^2+(I10-I12)^2+(J10-J12)^2) -> 3.4641016 | V24: =SQRT((D10-D13)^2+(E10-E13)^2+(F10-F13)^2+(G10-G13)^2+(H10-H13)^2+(I10-I13)^2+(J10-J13)^2) -> 3.6055513 | W24: =SQRT((D10-D14)^2+(E10-E14)^2+(F10-F14)^2+(G10-G14)^2+(H10-H14)^2+(I10-I14)^2+(J10-J14)^2) -> 3 | X24: =SQRT((D10-D15)^2+(E10-E15)^2+(F10-F15)^2+(G10-G15)^2+(H10-H15)^2+(I10-I15)^2+(J10-J15)^2) -> 8
M25: =B11 -> 6 | N25: =C11 -> Fitri Handayani | O25: =SQRT((D11-D6)^2+(E11-E6)^2+(F11-F6)^2+(G11-G6)^2+(H11-H6)^2+(I11-I6)^2+(J11-J6)^2) -> 9.9498744 | P25: =SQRT((D11-D7)^2+(E11-E7)^2+(F11-F7)^2+(G11-G7)^2+(H11-H7)^2+(I11-I7)^2+(J11-J7)^2) -> 2.6457513 | Q25: =SQRT((D11-D8)^2+(E11-E8)^2+(F11-F8)^2+(G11-G8)^2+(H11-H8)^2+(I11-I8)^2+(J11-J8)^2) -> 11.489125 | R25: =SQRT((D11-D9)^2+(E11-E9)^2+(F11-F9)^2+(G11-G9)^2+(H11-H9)^2+(I11-I9)^2+(J11-J9)^2) -> 4 | S25: =SQRT((D11-D10)^2+(E11-E10)^2+(F11-F10)^2+(G11-G10)^2+(H11-H10)^2+(I11-I10)^2+(J11-J10)^2) -> 7.9372539 | T25: 0 | U25: =SQRT((D11-D12)^2+(E11-E12)^2+(F11-F12)^2+(G11-G12)^2+(H11-H12)^2+(I11-I12)^2+(J11-J12)^2) -> 11.090537 | V25: =SQRT((D11-D13)^2+(E11-E13)^2+(F11-F13)^2+(G11-G13)^2+(H11-H13)^2+(I11-I13)^2+(J11-J13)^2) -> 5.8309519 | W25: =SQRT((D11-D14)^2+(E11-E14)^2+(F11-F14)^2+(G11-G14)^2+(H11-H14)^2+(I11-I14)^2+(J11-J14)^2) -> 10.677078 | X25: =SQRT((D11-D15)^2+(E11-E15)^2+(F11-F15)^2+(G11-G15)^2+(H11-H15)^2+(I11-I15)^2+(J11-J15)^2) -> 2.6457513
M26: =B12 -> 7 | N26: =C12 -> Galih Nugroho | O26: =SQRT((D12-D6)^2+(E12-E6)^2+(F12-F6)^2+(G12-G6)^2+(H12-H6)^2+(I12-I6)^2+(J12-J6)^2) -> 2.8284271 | P26: =SQRT((D12-D7)^2+(E12-E7)^2+(F12-F7)^2+(G12-G7)^2+(H12-H7)^2+(I12-I7)^2+(J12-J7)^2) -> 8.4852814 | Q26: =SQRT((D12-D8)^2+(E12-E8)^2+(F12-F8)^2+(G12-G8)^2+(H12-H8)^2+(I12-I8)^2+(J12-J8)^2) -> 2.236068 | R26: =SQRT((D12-D9)^2+(E12-E9)^2+(F12-F9)^2+(G12-G9)^2+(H12-H9)^2+(I12-I9)^2+(J12-J9)^2) -> 8.1853528 | S26: =SQRT((D12-D10)^2+(E12-E10)^2+(F12-F10)^2+(G12-G10)^2+(H12-H10)^2+(I12-I10)^2+(J12-J10)^2) -> 3.4641016 | T26: =SQRT((D12-D11)^2+(E12-E11)^2+(F12-F11)^2+(G12-G11)^2+(H12-H11)^2+(I12-I11)^2+(J12-J11)^2) -> 11.090537 | U26: 0 | V26: =SQRT((D12-D13)^2+(E12-E13)^2+(F12-F13)^2+(G12-G13)^2+(H12-H13)^2+(I12-I13)^2+(J12-J13)^2) -> 6.0827625 | W26: =SQRT((D12-D14)^2+(E12-E14)^2+(F12-F14)^2+(G12-G14)^2+(H12-H14)^2+(I12-I14)^2+(J12-J14)^2) -> 2.236068 | X26: =SQRT((D12-D15)^2+(E12-E15)^2+(F12-F15)^2+(G12-G15)^2+(H12-H15)^2+(I12-I15)^2+(J12-J15)^2) -> 10.77033
M27: =B13 -> 8 | N27: =C13 -> Hana Putri | O27: =SQRT((D13-D6)^2+(E13-E6)^2+(F13-F6)^2+(G13-G6)^2+(H13-H6)^2+(I13-I6)^2+(J13-J6)^2) -> 4.3588989 | P27: =SQRT((D13-D7)^2+(E13-E7)^2+(F13-F7)^2+(G13-G7)^2+(H13-H7)^2+(I13-I7)^2+(J13-J7)^2) -> 3.6055513 | Q27: =SQRT((D13-D8)^2+(E13-E8)^2+(F13-F8)^2+(G13-G8)^2+(H13-H8)^2+(I13-I8)^2+(J13-J8)^2) -> 6.3245553 | R27: =SQRT((D13-D9)^2+(E13-E9)^2+(F13-F9)^2+(G13-G9)^2+(H13-H9)^2+(I13-I9)^2+(J13-J9)^2) -> 2.4494897 | S27: =SQRT((D13-D10)^2+(E13-E10)^2+(F13-F10)^2+(G13-G10)^2+(H13-H10)^2+(I13-I10)^2+(J13-J10)^2) -> 3.6055513 | T27: =SQRT((D13-D11)^2+(E13-E11)^2+(F13-F11)^2+(G13-G11)^2+(H13-H11)^2+(I13-I11)^2+(J13-J11)^2) -> 5.8309519 | U27: =SQRT((D13-D12)^2+(E13-E12)^2+(F13-F12)^2+(G13-G12)^2+(H13-H12)^2+(I13-I12)^2+(J13-J12)^2) -> 6.0827625 | V27: 0 | W27: =SQRT((D13-D14)^2+(E13-E14)^2+(F13-F14)^2+(G13-G14)^2+(H13-H14)^2+(I13-I14)^2+(J13-J14)^2) -> 5.6568542 | X27: =SQRT((D13-D15)^2+(E13-E15)^2+(F13-F15)^2+(G13-G15)^2+(H13-H15)^2+(I13-I15)^2+(J13-J15)^2) -> 5
M28: =B14 -> 9 | N28: =C14 -> Indra Kusuma | O28: =SQRT((D14-D6)^2+(E14-E6)^2+(F14-F6)^2+(G14-G6)^2+(H14-H6)^2+(I14-I6)^2+(J14-J6)^2) -> 3 | P28: =SQRT((D14-D7)^2+(E14-E7)^2+(F14-F7)^2+(G14-G7)^2+(H14-H7)^2+(I14-I7)^2+(J14-J7)^2) -> 8.0622577 | Q28: =SQRT((D14-D8)^2+(E14-E8)^2+(F14-F8)^2+(G14-G8)^2+(H14-H8)^2+(I14-I8)^2+(J14-J8)^2) -> 2 | R28: =SQRT((D14-D9)^2+(E14-E9)^2+(F14-F9)^2+(G14-G9)^2+(H14-H9)^2+(I14-I9)^2+(J14-J9)^2) -> 7.8740079 | S28: =SQRT((D14-D10)^2+(E14-E10)^2+(F14-F10)^2+(G14-G10)^2+(H14-H10)^2+(I14-I10)^2+(J14-J10)^2) -> 3 | T28: =SQRT((D14-D11)^2+(E14-E11)^2+(F14-F11)^2+(G14-G11)^2+(H14-H11)^2+(I14-I11)^2+(J14-J11)^2) -> 10.677078 | U28: =SQRT((D14-D12)^2+(E14-E12)^2+(F14-F12)^2+(G14-G12)^2+(H14-H12)^2+(I14-I12)^2+(J14-J12)^2) -> 2.236068 | V28: =SQRT((D14-D13)^2+(E14-E13)^2+(F14-F13)^2+(G14-G13)^2+(H14-H13)^2+(I14-I13)^2+(J14-J13)^2) -> 5.6568542 | W28: 0 | X28: =SQRT((D14-D15)^2+(E14-E15)^2+(F14-F15)^2+(G14-G15)^2+(H14-H15)^2+(I14-I15)^2+(J14-J15)^2) -> 10.440307
M29: =B15 -> 10 | N29: =C15 -> Joko Purnomo | O29: =SQRT((D15-D6)^2+(E15-E6)^2+(F15-F6)^2+(G15-G6)^2+(H15-H6)^2+(I15-I6)^2+(J15-J6)^2) -> 9.1651514 | P29: =SQRT((D15-D7)^2+(E15-E7)^2+(F15-F7)^2+(G15-G7)^2+(H15-H7)^2+(I15-I7)^2+(J15-J7)^2) -> 3.4641016 | Q29: =SQRT((D15-D8)^2+(E15-E8)^2+(F15-F8)^2+(G15-G8)^2+(H15-H8)^2+(I15-I8)^2+(J15-J8)^2) -> 11.090537 | R29: =SQRT((D15-D9)^2+(E15-E9)^2+(F15-F9)^2+(G15-G9)^2+(H15-H9)^2+(I15-I9)^2+(J15-J9)^2) -> 2.6457513 | S29: =SQRT((D15-D10)^2+(E15-E10)^2+(F15-F10)^2+(G15-G10)^2+(H15-H10)^2+(I15-I10)^2+(J15-J10)^2) -> 8 | T29: =SQRT((D15-D11)^2+(E15-E11)^2+(F15-F11)^2+(G15-G11)^2+(H15-H11)^2+(I15-I11)^2+(J15-J11)^2) -> 2.6457513 | U29: =SQRT((D15-D12)^2+(E15-E12)^2+(F15-F12)^2+(G15-G12)^2+(H15-H12)^2+(I15-I12)^2+(J15-J12)^2) -> 10.77033 | V29: =SQRT((D15-D13)^2+(E15-E13)^2+(F15-F13)^2+(G15-G13)^2+(H15-H13)^2+(I15-I13)^2+(J15-J13)^2) -> 5 | W29: =SQRT((D15-D14)^2+(E15-E14)^2+(F15-F14)^2+(G15-G14)^2+(H15-H14)^2+(I15-I14)^2+(J15-J14)^2) -> 10.440307 | X29: 0
B32: C. a(i) — RATA-RATA JARAK KE ANGGOTA KLASTER SENDIRI
B33: No | C33: Nama | D33: Klaster | E33: n klaster | F33: Σ jarak sesama | G33: a(i) | H33: Interpretasi
B34: =B6 -> 1 | C34: =C6 -> Andi Setiawan | D34: =K6 -> K1 | E34: =COUNTIF(K$6:K$15,K6) -> 4 | F34: =(IF(K6=K6,O20,0)+IF(K7=K6,P20,0)+IF(K8=K6,Q20,0)+IF(K9=K6,R20,0)+IF(K10=K6,S20,0)+IF(K11=K6,T20,0)+IF(K12=K6,U20,0)+IF(K13=K6,V20,0)+IF(K14=K6,W20,0)+IF(K15=K6,X20,0)) -> 8.8284271 | G34: =IFERROR((IF(K6=K6,O20,0)+IF(K7=K6,P20,0)+IF(K8=K6,Q20,0)+IF(K9=K6,R20,0)+IF(K10=K6,S20,0)+IF(K11=K6,T20,0)+IF(K12=K6,U20,0)+IF(K13=K6,V20,0)+IF(K14=K6,W20,0)+IF(K15=K6,X20,0))/(E34-1),0) -> 2.942809 | H34: =IF(G34<1,"Kohesi sangat tinggi",IF(G34<2,"Kohesi tinggi",IF(G34<3,"Kohesi sedang","Kohesi rendah"))) -> Kohesi sedang
B35: =B7 -> 2 | C35: =C7 -> Budi Santoso | D35: =K7 -> K3 | E35: =COUNTIF(K$6:K$15,K7) -> 4 | F35: =(IF(K6=K7,O21,0)+IF(K7=K7,P21,0)+IF(K8=K7,Q21,0)+IF(K9=K7,R21,0)+IF(K10=K7,S21,0)+IF(K11=K7,T21,0)+IF(K12=K7,U21,0)+IF(K13=K7,V21,0)+IF(K14=K7,W21,0)+IF(K15=K7,X21,0)) -> 8.7556042 | G35: =IFERROR((IF(K6=K7,O21,0)+IF(K7=K7,P21,0)+IF(K8=K7,Q21,0)+IF(K9=K7,R21,0)+IF(K10=K7,S21,0)+IF(K11=K7,T21,0)+IF(K12=K7,U21,0)+IF(K13=K7,V21,0)+IF(K14=K7,W21,0)+IF(K15=K7,X21,0))/(E35-1),0) -> 2.9185347 | H35: =IF(G35<1,"Kohesi sangat tinggi",IF(G35<2,"Kohesi tinggi",IF(G35<3,"Kohesi sedang","Kohesi rendah"))) -> Kohesi sedang
B36: =B8 -> 3 | C36: =C8 -> Citra Dewi | D36: =K8 -> K1 | E36: =COUNTIF(K$6:K$15,K8) -> 4 | F36: =(IF(K6=K8,O22,0)+IF(K7=K8,P22,0)+IF(K8=K8,Q22,0)+IF(K9=K8,R22,0)+IF(K10=K8,S22,0)+IF(K11=K8,T22,0)+IF(K12=K8,U22,0)+IF(K13=K8,V22,0)+IF(K14=K8,W22,0)+IF(K15=K8,X22,0)) -> 7.236068 | G36: =IFERROR((IF(K6=K8,O22,0)+IF(K7=K8,P22,0)+IF(K8=K8,Q22,0)+IF(K9=K8,R22,0)+IF(K10=K8,S22,0)+IF(K11=K8,T22,0)+IF(K12=K8,U22,0)+IF(K13=K8,V22,0)+IF(K14=K8,W22,0)+IF(K15=K8,X22,0))/(E36-1),0) -> 2.4120227 | H36: =IF(G36<1,"Kohesi sangat tinggi",IF(G36<2,"Kohesi tinggi",IF(G36<3,"Kohesi sedang","Kohesi rendah"))) -> Kohesi sedang
B37: =B9 -> 4 | C37: =C9 -> Dian Pratiwi | D37: =K9 -> K3 | E37: =COUNTIF(K$6:K$15,K9) -> 4 | F37: =(IF(K6=K9,O23,0)+IF(K7=K9,P23,0)+IF(K8=K9,Q23,0)+IF(K9=K9,R23,0)+IF(K10=K9,S23,0)+IF(K11=K9,T23,0)+IF(K12=K9,U23,0)+IF(K13=K9,V23,0)+IF(K14=K9,W23,0)+IF(K15=K9,X23,0)) -> 9.2915026 | G37: =IFERROR((IF(K6=K9,O23,0)+IF(K7=K9,P23,0)+IF(K8=K9,Q23,0)+IF(K9=K9,R23,0)+IF(K10=K9,S23,0)+IF(K11=K9,T23,0)+IF(K12=K9,U23,0)+IF(K13=K9,V23,0)+IF(K14=K9,W23,0)+IF(K15=K9,X23,0))/(E37-1),0) -> 3.0971675 | H37: =IF(G37<1,"Kohesi sangat tinggi",IF(G37<2,"Kohesi tinggi",IF(G37<3,"Kohesi sedang","Kohesi rendah"))) -> Kohesi rendah
B38: =B10 -> 5 | C38: =C10 -> Eko Wahyudi | D38: =K10 -> K2 | E38: =COUNTIF(K$6:K$15,K10) -> 2 | F38: =(IF(K6=K10,O24,0)+IF(K7=K10,P24,0)+IF(K8=K10,Q24,0)+IF(K9=K10,R24,0)+IF(K10=K10,S24,0)+IF(K11=K10,T24,0)+IF(K12=K10,U24,0)+IF(K13=K10,V24,0)+IF(K14=K10,W24,0)+IF(K15=K10,X24,0)) -> 3.6055513 | G38: =IFERROR((IF(K6=K10,O24,0)+IF(K7=K10,P24,0)+IF(K8=K10,Q24,0)+IF(K9=K10,R24,0)+IF(K10=K10,S24,0)+IF(K11=K10,T24,0)+IF(K12=K10,U24,0)+IF(K13=K10,V24,0)+IF(K14=K10,W24,0)+IF(K15=K10,X24,0))/(E38-1),0) -> 3.6055513 | H38: =IF(G38<1,"Kohesi sangat tinggi",IF(G38<2,"Kohesi tinggi",IF(G38<3,"Kohesi sedang","Kohesi rendah"))) -> Kohesi rendah
B39: =B11 -> 6 | C39: =C11 -> Fitri Handayani | D39: =K11 -> K3 | E39: =COUNTIF(K$6:K$15,K11) -> 4 | F39: =(IF(K6=K11,O25,0)+IF(K7=K11,P25,0)+IF(K8=K11,Q25,0)+IF(K9=K11,R25,0)+IF(K10=K11,S25,0)+IF(K11=K11,T25,0)+IF(K12=K11,U25,0)+IF(K13=K11,V25,0)+IF(K14=K11,W25,0)+IF(K15=K11,X25,0)) -> 9.2915026 | G39: =IFERROR((IF(K6=K11,O25,0)+IF(K7=K11,P25,0)+IF(K8=K11,Q25,0)+IF(K9=K11,R25,0)+IF(K10=K11,S25,0)+IF(K11=K11,T25,0)+IF(K12=K11,U25,0)+IF(K13=K11,V25,0)+IF(K14=K11,W25,0)+IF(K15=K11,X25,0))/(E39-1),0) -> 3.0971675 | H39: =IF(G39<1,"Kohesi sangat tinggi",IF(G39<2,"Kohesi tinggi",IF(G39<3,"Kohesi sedang","Kohesi rendah"))) -> Kohesi rendah
B40: =B12 -> 7 | C40: =C12 -> Galih Nugroho | D40: =K12 -> K1 | E40: =COUNTIF(K$6:K$15,K12) -> 4 | F40: =(IF(K6=K12,O26,0)+IF(K7=K12,P26,0)+IF(K8=K12,Q26,0)+IF(K9=K12,R26,0)+IF(K10=K12,S26,0)+IF(K11=K12,T26,0)+IF(K12=K12,U26,0)+IF(K13=K12,V26,0)+IF(K14=K12,W26,0)+IF(K15=K12,X26,0)) -> 7.3005631 | G40: =IFERROR((IF(K6=K12,O26,0)+IF(K7=K12,P26,0)+IF(K8=K12,Q26,0)+IF(K9=K12,R26,0)+IF(K10=K12,S26,0)+IF(K11=K12,T26,0)+IF(K12=K12,U26,0)+IF(K13=K12,V26,0)+IF(K14=K12,W26,0)+IF(K15=K12,X26,0))/(E40-1),0) -> 2.433521 | H40: =IF(G40<1,"Kohesi sangat tinggi",IF(G40<2,"Kohesi tinggi",IF(G40<3,"Kohesi sedang","Kohesi rendah"))) -> Kohesi sedang
B41: =B13 -> 8 | C41: =C13 -> Hana Putri | D41: =K13 -> K2 | E41: =COUNTIF(K$6:K$15,K13) -> 2 | F41: =(IF(K6=K13,O27,0)+IF(K7=K13,P27,0)+IF(K8=K13,Q27,0)+IF(K9=K13,R27,0)+IF(K10=K13,S27,0)+IF(K11=K13,T27,0)+IF(K12=K13,U27,0)+IF(K13=K13,V27,0)+IF(K14=K13,W27,0)+IF(K15=K13,X27,0)) -> 3.6055513 | G41: =IFERROR((IF(K6=K13,O27,0)+IF(K7=K13,P27,0)+IF(K8=K13,Q27,0)+IF(K9=K13,R27,0)+IF(K10=K13,S27,0)+IF(K11=K13,T27,0)+IF(K12=K13,U27,0)+IF(K13=K13,V27,0)+IF(K14=K13,W27,0)+IF(K15=K13,X27,0))/(E41-1),0) -> 3.6055513 | H41: =IF(G41<1,"Kohesi sangat tinggi",IF(G41<2,"Kohesi tinggi",IF(G41<3,"Kohesi sedang","Kohesi rendah"))) -> Kohesi rendah
B42: =B14 -> 9 | C42: =C14 -> Indra Kusuma | D42: =K14 -> K1 | E42: =COUNTIF(K$6:K$15,K14) -> 4 | F42: =(IF(K6=K14,O28,0)+IF(K7=K14,P28,0)+IF(K8=K14,Q28,0)+IF(K9=K14,R28,0)+IF(K10=K14,S28,0)+IF(K11=K14,T28,0)+IF(K12=K14,U28,0)+IF(K13=K14,V28,0)+IF(K14=K14,W28,0)+IF(K15=K14,X28,0)) -> 7.236068 | G42: =IFERROR((IF(K6=K14,O28,0)+IF(K7=K14,P28,0)+IF(K8=K14,Q28,0)+IF(K9=K14,R28,0)+IF(K10=K14,S28,0)+IF(K11=K14,T28,0)+IF(K12=K14,U28,0)+IF(K13=K14,V28,0)+IF(K14=K14,W28,0)+IF(K15=K14,X28,0))/(E42-1),0) -> 2.4120227 | H42: =IF(G42<1,"Kohesi sangat tinggi",IF(G42<2,"Kohesi tinggi",IF(G42<3,"Kohesi sedang","Kohesi rendah"))) -> Kohesi sedang
B43: =B15 -> 10 | C43: =C15 -> Joko Purnomo | D43: =K15 -> K3 | E43: =COUNTIF(K$6:K$15,K15) -> 4 | F43: =(IF(K6=K15,O29,0)+IF(K7=K15,P29,0)+IF(K8=K15,Q29,0)+IF(K9=K15,R29,0)+IF(K10=K15,S29,0)+IF(K11=K15,T29,0)+IF(K12=K15,U29,0)+IF(K13=K15,V29,0)+IF(K14=K15,W29,0)+IF(K15=K15,X29,0)) -> 8.7556042 | G43: =IFERROR((IF(K6=K15,O29,0)+IF(K7=K15,P29,0)+IF(K8=K15,Q29,0)+IF(K9=K15,R29,0)+IF(K10=K15,S29,0)+IF(K11=K15,T29,0)+IF(K12=K15,U29,0)+IF(K13=K15,V29,0)+IF(K14=K15,W29,0)+IF(K15=K15,X29,0))/(E43-1),0) -> 2.9185347 | H43: =IF(G43<1,"Kohesi sangat tinggi",IF(G43<2,"Kohesi tinggi",IF(G43<3,"Kohesi sedang","Kohesi rendah"))) -> Kohesi sedang
B46: D. b(i) — RATA-RATA JARAK KE KLASTER TERDEKAT LAINNYA | b(i) = MIN avg ke klaster lain
B47: No | C47: Nama | D47: Klaster | E47: avg→K1 | F47: avg→K2 | G47: avg→K3 | H47: b(i) | I47: Klaster terdekat
...

Sheet TAHAP 2 – AHP
B1: TAHAP 2: PEMBOBOTAN KRITERIA – ANALYTICAL HIERARCHY PROCESS (AHP)
B2: Pairwise Matrix = Input Pakar | Normalisasi & CR = Formula Excel
B4: A. MATRIKS PERBANDINGAN BERPASANGAN — Input Pakar (Skala 1–9 Saaty)
B5: Kriteria / Kriteria | C5: C1: Komp. Klinis | D5: C2: Profesionalisme | E5: C3: Kolaborasi Tim | F5: C4: Orientasi Hasil | G5: C5: Keselamatan | H5: C6: Mgmt Waktu | I5: C7: Komunikasi
B6: C1: Komp. Klinis | C6: 1 | D6: 3 | E6: 5 | F6: 7 | G6: 5 | H6: 7 | I6: 9
B7: C2: Profesionalisme | C7: =1/D6 -> 0.33333333 | D7: 1 | E7: 3 | F7: 5 | G7: 3 | H7: 5 | I7: 7
B8: C3: Kolaborasi Tim | C8: =1/E6 -> 0.2 | D8: =1/E7 -> 0.33333333 | E8: 1 | F8: 3 | G8: 1 | H8: 3 | I8: 5
B9: C4: Orientasi Hasil | C9: =1/F6 -> 0.14285714 | D9: =1/F7 -> 0.2 | E9: =1/F8 -> 0.33333333 | F9: 1 | G9: 0.33333333 | H9: 1 | I9: 3
B10: C5: Keselamatan | C10: =1/G6 -> 0.2 | D10: =1/G7 -> 0.33333333 | E10: =1/G8 -> 1 | F10: =1/G9 -> 3 | G10: 1 | H10: 3 | I10: 5
B11: C6: Mgmt Waktu | C11: =1/H6 -> 0.14285714 | D11: =1/H7 -> 0.2 | E11: =1/H8 -> 0.33333333 | F11: =1/H9 -> 1 | G11: =1/H10 -> 0.33333333 | H11: 1 | I11: 3
B12: C7: Komunikasi | C12: =1/I6 -> 0.11111111 | D12: =1/I7 -> 0.14285714 | E12: =1/I8 -> 0.2 | F12: =1/I9 -> 0.33333333 | G12: =1/I10 -> 0.2 | H12: =1/I11 -> 0.33333333 | I12: 1
B13: JUMLAH KOLOM | C13: =SUM(C6:C12) -> 2.1301587 | D13: =SUM(D6:D12) -> 5.2095238 | E13: =SUM(E6:E12) -> 10.866667 | F13: =SUM(F6:F12) -> 20.333333 | G13: =SUM(G6:G12) -> 10.866667 | H13: =SUM(H6:H12) -> 20.333333 | I13: =SUM(I6:I12) -> 33
B15: B. MATRIKS NORMALISASI (rij = xij / jumlah kolom-j) & BOBOT PRIORITAS
B16: Kriteria | C16: C1: Komp. Klinis | D16: C2: Profesionalisme | E16: C3: Kolaborasi Tim | F16: C4: Orientasi Hasil | G16: C5: Keselamatan | H16: C6: Mgmt Waktu | I16: C7: Komunikasi | J16: Bobot (W)
B17: C1: Komp. Klinis | C17: =C6/C13 -> 0.46944858 | D17: =D6/D13 -> 0.57586837 | E17: =E6/E13 -> 0.4601227 | F17: =F6/F13 -> 0.3442623 | G17: =G6/G13 -> 0.4601227 | H17: =H6/H13 -> 0.3442623 | I17: =I6/I13 -> 0.27272727 | J17: =AVERAGE(C17:I17) -> 0.41811632 | P17: =C6/C13 -> 0.46944858 | Q17: =D6/D13 -> 0.57586837 | R17: =E6/E13 -> 0.4601227 | S17: =F6/F13 -> 0.3442623 | T17: =G6/G13 -> 0.4601227 | U17: =H6/H13 -> 0.3442623 | V17: =I6/I13 -> 0.27272727
B18: C2: Profesionalisme | C18: =C7/C13 -> 0.15648286 | D18: =D7/D13 -> 0.19195612 | E18: =E7/E13 -> 0.27607362 | F18: =F7/F13 -> 0.24590164 | G18: =G7/G13 -> 0.27607362 | H18: =H7/H13 -> 0.24590164 | I18: =I7/I13 -> 0.21212121 | J18: =AVERAGE(C18:I18) -> 0.22921582 | P18: =C7/C13 -> 0.15648286 | Q18: =D7/D13 -> 0.19195612 | R18: =E7/E13 -> 0.27607362 | S18: =F7/F13 -> 0.24590164 | T18: =G7/G13 -> 0.27607362 | U18: =H7/H13 -> 0.24590164 | V18: =I7/I13 -> 0.21212121
B19: C3: Kolaborasi Tim | C19: =C8/C13 -> 0.093889717 | D19: =D8/D13 -> 0.063985375 | E19: =E8/E13 -> 0.09202454 | F19: =F8/F13 -> 0.14754098 | G19: =G8/G13 -> 0.09202454 | H19: =H8/H13 -> 0.14754098 | I19: =I8/I13 -> 0.15151515 | J19: =AVERAGE(C19:I19) -> 0.1126459 | P19: =C8/C13 -> 0.093889717 | Q19: =D8/D13 -> 0.063985375 | R19: =E8/E13 -> 0.09202454 | S19: =F8/F13 -> 0.14754098 | T19: =G8/G13 -> 0.09202454 | U19: =H8/H13 -> 0.14754098 | V19: =I8/I13 -> 0.15151515
B20: C4: Orientasi Hasil | C20: =C9/C13 -> 0.067064083 | D20: =D9/D13 -> 0.038391225 | E20: =E9/E13 -> 0.030674847 | F20: =F9/F13 -> 0.049180328 | G20: =G9/G13 -> 0.030674847 | H20: =H9/H13 -> 0.049180328 | I20: =I9/I13 -> 0.090909091 | J20: =AVERAGE(C20:I20) -> 0.050867821 | P20: =C9/C13 -> 0.067064083 | Q20: =D9/D13 -> 0.038391225 | R20: =E9/E13 -> 0.030674847 | S20: =F9/F13 -> 0.049180328 | T20: =G9/G13 -> 0.030674847 | U20: =H9/H13 -> 0.049180328 | V20: =I9/I13 -> 0.090909091
B21: C5: Keselamatan | C21: =C10/C13 -> 0.093889717 | D21: =D10/D13 -> 0.063985375 | E21: =E10/E13 -> 0.09202454 | F21: =F10/F13 -> 0.14754098 | G21: =G10/G13 -> 0.09202454 | H21: =H10/H13 -> 0.14754098 | I21: =I10/I13 -> 0.15151515 | J21: =AVERAGE(C21:I21) -> 0.1126459 | P21: =C10/C13 -> 0.093889717 | Q21: =D10/D13 -> 0.063985375 | R21: =E10/E13 -> 0.09202454 | S21: =F10/F13 -> 0.14754098 | T21: =G10/G13 -> 0.09202454 | U21: =H10/H13 -> 0.14754098 | V21: =I10/I13 -> 0.15151515
B22: C6: Mgmt Waktu | C22: =C11/C13 -> 0.067064083 | D22: =D11/D13 -> 0.038391225 | E22: =E11/E13 -> 0.030674847 | F22: =F11/F13 -> 0.049180328 | G22: =G11/G13 -> 0.030674847 | H22: =H11/H13 -> 0.049180328 | I22: =I11/I13 -> 0.090909091 | J22: =AVERAGE(C22:I22) -> 0.050867821 | P22: =C11/C13 -> 0.067064083 | Q22: =D11/D13 -> 0.038391225 | R22: =E11/E13 -> 0.030674847 | S22: =F11/F13 -> 0.049180328 | T22: =G11/G13 -> 0.030674847 | U22: =H11/H13 -> 0.049180328 | V22: =I11/I13 -> 0.090909091
B23: C7: Komunikasi | C23: =C12/C13 -> 0.052160954 | D23: =D12/D13 -> 0.027422303 | E23: =E12/E13 -> 0.018404908 | F23: =F12/F13 -> 0.016393443 | G23: =G12/G13 -> 0.018404908 | H23: =H12/H13 -> 0.016393443 | I23: =I12/I13 -> 0.03030303 | J23: =AVERAGE(C23:I23) -> 0.025640427 | P23: =C12/C13 -> 0.052160954 | Q23: =D12/D13 -> 0.027422303 | R23: =E12/E13 -> 0.018404908 | S23: =F12/F13 -> 0.016393443 | T23: =G12/G13 -> 0.018404908 | U23: =H12/H13 -> 0.016393443 | V23: =I12/I13 -> 0.03030303
B25: C. UJI KONSISTENSI (Consistency Ratio — CR < 0.1)
B26: Weighted Sum Vector (WSV) | C26: =C6*J17+D6*J18+E6*J19+F6*J20+G6*J21+H6*J22+I6*J23 -> 3.1751361 | D26: =C7*J17+D7*J18+E7*J19+F7*J20+G7*J21+H7*J22+I7*J23 -> 1.7326245 | E26: =C8*J17+D8*J18+E8*J19+F8*J20+G8*J21+H8*J22+I8*J23 -> 0.81872939 | F26: =C9*J17+D9*J18+E9*J19+F9*J20+G9*J21+H9*J22+I9*J23 -> 0.35932825 | G26: =C10*J17+D10*J18+E10*J19+F10*J20+G10*J21+H10*J22+I10*J23 -> 0.81872939 | H26: =C11*J17+D11*J18+E11*J19+F11*J20+G11*J21+H11*J22+I11*J23 -> 0.35932825 | I26: =C12*J17+D12*J18+E12*J19+F12*J20+G12*J21+H12*J22+I12*J23 -> 0.18381315
B27: Lambda Vector (λi = WSV / Wi) | C27: =C26/J17 -> 7.5939062 | D27: =D26/J18 -> 7.5589222 | E27: =E26/J19 -> 7.2681687 | F27: =F26/J20 -> 7.06396 | G27: =G26/J21 -> 7.2681687 | H27: =H26/J22 -> 7.06396 | I27: =I26/J23 -> 7.1688803
B28: n (Jumlah Kriteria) | C28: 7
B29: λmax = AVERAGE(λi) | C29: =AVERAGE(C27:I27) -> 7.2837094
B30: CI = (λmax − n) / (n−1) | C30: =(C29-C28)/(C28-1) -> 0.047284907
B31: RI (n=7, tabel Saaty) | C31: 1.32
B32: CR = CI / RI | C32: =C30/C31 -> 0.0358219
B33: Status Konsistensi | C33: =IF(C32<0.1,"✔ KONSISTEN (CR < 0.1)","✘ TIDAK KONSISTEN") -> ✔ KONSISTEN (CR < 0.1)

Sheet TAHAP 3 – WP
B1: TAHAP 3: AGREGASI NILAI KINERJA — WEIGHTED PRODUCT (WP)
B2: Formula: Si = ∏(Xij ^ Wj) | Bobot diambil dari Sheet AHP (formula referencing)
B4: A. BOBOT KRITERIA (Referensi dari Sheet TAHAP 2 – AHP)
B5: Kriteria/Perawat | C5: C1 | D5: C2 | E5: C3 | F5: C4 | G5: C5 | H5: C6 | I5: C7 | J5: WP Score (Si) | K5: Rank WP | L5: Klaster
B6: Bobot (W) | C6: ='TAHAP 2 – AHP'!J17 -> 0.41811632 | D6: ='TAHAP 2 – AHP'!J18 -> 0.22921582 | E6: ='TAHAP 2 – AHP'!J19 -> 0.1126459 | F6: ='TAHAP 2 – AHP'!J20 -> 0.050867821 | G6: ='TAHAP 2 – AHP'!J21 -> 0.1126459 | H6: ='TAHAP 2 – AHP'!J22 -> 0.050867821 | I6: ='TAHAP 2 – AHP'!J23 -> 0.025640427
B7: B. DATA KINERJA & PERHITUNGAN WP SCORE
B8: No | C8: Nama Perawat | D8: C1 | E8: C2 | F8: C3 | G8: C4 | H8: C5 | I8: C6 | J8: C7 | K8: WP Score (Si) | L8: Rank WP | M8: Klaster
B9: 1 | C9: ='TAHAP 1 – K-MEANS'!C6 -> Andi Setiawan | D9: ='TAHAP 1 – K-MEANS'!D6 -> 8 | E9: ='TAHAP 1 – K-MEANS'!E6 -> 7 | F9: ='TAHAP 1 – K-MEANS'!F6 -> 9 | G9: ='TAHAP 1 – K-MEANS'!G6 -> 8 | H9: ='TAHAP 1 – K-MEANS'!H6 -> 9 | I9: ='TAHAP 1 – K-MEANS'!I6 -> 7 | J9: ='TAHAP 1 – K-MEANS'!J6 -> 8 | K9: =(D9^C6)*(E9^D6)*(F9^E6)*(G9^F6)*(H9^G6)*(I9^H6)*(J9^I6) -> 7.9135552 | L9: =RANK(K9,K9:K18,0) -> 4 | M9: ='TAHAP 1 – K-MEANS'!M6 -> K1
B10: 2 | C10: ='TAHAP 1 – K-MEANS'!C7 -> Budi Santoso | D10: ='TAHAP 1 – K-MEANS'!D7 -> 5 | E10: ='TAHAP 1 – K-MEANS'!E7 -> 6 | F10: ='TAHAP 1 – K-MEANS'!F7 -> 5 | G10: ='TAHAP 1 – K-MEANS'!G7 -> 6 | H10: ='TAHAP 1 – K-MEANS'!H7 -> 5 | I10: ='TAHAP 1 – K-MEANS'!I7 -> 6 | J10: ='TAHAP 1 – K-MEANS'!J7 -> 5 | K10: =(D10^C6)*(E10^D6)*(F10^E6)*(G10^F6)*(H10^G6)*(I10^H6)*(J10^I6) -> 5.310986 | L10: =RANK(K10,K9:K18,0) -> 8 | M10: ='TAHAP 1 – K-MEANS'!M7 -> K3
B11: 3 | C11: ='TAHAP 1 – K-MEANS'!C8 -> Citra Dewi | D11: ='TAHAP 1 – K-MEANS'!D8 -> 9 | E11: ='TAHAP 1 – K-MEANS'!E8 -> 9 | F11: ='TAHAP 1 – K-MEANS'!F8 -> 8 | G11: ='TAHAP 1 – K-MEANS'!G8 -> 9 | H11: ='TAHAP 1 – K-MEANS'!H8 -> 9 | I11: ='TAHAP 1 – K-MEANS'!I8 -> 8 | J11: ='TAHAP 1 – K-MEANS'!J8 -> 9 | K11: =(D11^C6)*(E11^D6)*(F11^E6)*(G11^F6)*(H11^G6)*(I11^H6)*(J11^I6) -> 8.8283262 | L11: =RANK(K11,K9:K18,0) -> 1 | M11: ='TAHAP 1 – K-MEANS'!M8 -> K1
B12: 4 | C12: ='TAHAP 1 – K-MEANS'!C9 -> Dian Pratiwi | D12: ='TAHAP 1 – K-MEANS'!D9 -> 6 | E12: ='TAHAP 1 – K-MEANS'!E9 -> 5 | F12: ='TAHAP 1 – K-MEANS'!F9 -> 6 | G12: ='TAHAP 1 – K-MEANS'!G9 -> 5 | H12: ='TAHAP 1 – K-MEANS'!H9 -> 6 | I12: ='TAHAP 1 – K-MEANS'!I9 -> 5 | J12: ='TAHAP 1 – K-MEANS'!J9 -> 6 | K12: =(D12^C6)*(E12^D6)*(F12^E6)*(G12^F6)*(H12^G6)*(I12^H6)*(J12^I6) -> 5.6486687 | L12: =RANK(K12,K9:K18,0) -> 7 | M12: ='TAHAP 1 – K-MEANS'!M9 -> K3
B13: 5 | C13: ='TAHAP 1 – K-MEANS'!C10 -> Eko Wahyudi | D13: ='TAHAP 1 – K-MEANS'!D10 -> 7 | E13: ='TAHAP 1 – K-MEANS'!E10 -> 8 | F13: ='TAHAP 1 – K-MEANS'!F10 -> 7 | G13: ='TAHAP 1 – K-MEANS'!G10 -> 8 | H13: ='TAHAP 1 – K-MEANS'!H10 -> 7 | I13: ='TAHAP 1 – K-MEANS'!I10 -> 8 | J13: ='TAHAP 1 – K-MEANS'!J10 -> 7 | K13: =(D13^C6)*(E13^D6)*(F13^E6)*(G13^F6)*(H13^G6)*(I13^H6)*(J13^I6) -> 7.3162841 | L13: =RANK(K13,K9:K18,0) -> 5 | M13: ='TAHAP 1 – K-MEANS'!M10 -> K2
B14: 6 | C14: ='TAHAP 1 – K-MEANS'!C11 -> Fitri Handayani | D14: ='TAHAP 1 – K-MEANS'!D11 -> 4 | E14: ='TAHAP 1 – K-MEANS'!E11 -> 5 | F14: ='TAHAP 1 – K-MEANS'!F11 -> 4 | G14: ='TAHAP 1 – K-MEANS'!G11 -> 5 | H14: ='TAHAP 1 – K-MEANS'!H11 -> 4 | I14: ='TAHAP 1 – K-MEANS'!I11 -> 5 | J14: ='TAHAP 1 – K-MEANS'!J11 -> 4 | K14: =(D14^C6)*(E14^D6)*(F14^E6)*(G14^F6)*(H14^G6)*(I14^H6)*(J14^I6) -> 4.3065798 | L14: =RANK(K14,K9:K18,0) -> 10 | M14: ='TAHAP 1 – K-MEANS'!M11 -> K3
B15: 7 | C15: ='TAHAP 1 – K-MEANS'!C12 -> Galih Nugroho | D15: ='TAHAP 1 – K-MEANS'!D12 -> 9 | E15: ='TAHAP 1 – K-MEANS'!E12 -> 8 | F15: ='TAHAP 1 – K-MEANS'!F12 -> 9 | G15: ='TAHAP 1 – K-MEANS'!G12 -> 9 | H15: ='TAHAP 1 – K-MEANS'!H12 -> 8 | I15: ='TAHAP 1 – K-MEANS'!I12 -> 9 | J15: ='TAHAP 1 – K-MEANS'!J12 -> 8 | K15: =(D15^C6)*(E15^D6)*(F15^E6)*(G15^F6)*(H15^G6)*(I15^H6)*(J15^I6) -> 8.6187414 | L15: =RANK(K15,K9:K18,0) -> 2 | M15: ='TAHAP 1 – K-MEANS'!M12 -> K1
B16: 8 | C16: ='TAHAP 1 – K-MEANS'!C13 -> Hana Putri | D16: ='TAHAP 1 – K-MEANS'!D13 -> 6 | E16: ='TAHAP 1 – K-MEANS'!E13 -> 6 | F16: ='TAHAP 1 – K-MEANS'!F13 -> 7 | G16: ='TAHAP 1 – K-MEANS'!G13 -> 6 | H16: ='TAHAP 1 – K-MEANS'!H13 -> 7 | I16: ='TAHAP 1 – K-MEANS'!I13 -> 6 | J16: ='TAHAP 1 – K-MEANS'!J13 -> 7 | K16: =(D16^C6)*(E16^D6)*(F16^E6)*(G16^F6)*(H16^G6)*(I16^H6)*(J16^I6) -> 6.2366354 | L16: =RANK(K16,K9:K18,0) -> 6 | M16: ='TAHAP 1 – K-MEANS'!M13 -> K2
B17: 9 | C17: ='TAHAP 1 – K-MEANS'!C14 -> Indra Kusuma | D17: ='TAHAP 1 – K-MEANS'!D14 -> 8 | E17: ='TAHAP 1 – K-MEANS'!E14 -> 9 | F17: ='TAHAP 1 – K-MEANS'!F14 -> 8 | G17: ='TAHAP 1 – K-MEANS'!G14 -> 8 | H17: ='TAHAP 1 – K-MEANS'!H14 -> 9 | I17: ='TAHAP 1 – K-MEANS'!I14 -> 9 | J17: ='TAHAP 1 – K-MEANS'!J14 -> 8 | K17: =(D17^C6)*(E17^D6)*(F17^E6)*(G17^F6)*(H17^G6)*(I17^H6)*(J17^I6) -> 8.3787473 | L17: =RANK(K17,K9:K18,0) -> 3 | M17: ='TAHAP 1 – K-MEANS'!M14 -> K1
B18: 10 | C18: ='TAHAP 1 – K-MEANS'!C15 -> Joko Purnomo | D18: ='TAHAP 1 – K-MEANS'!D15 -> 5 | E18: ='TAHAP 1 – K-MEANS'!E15 -> 4 | F18: ='TAHAP 1 – K-MEANS'!F15 -> 5 | G18: ='TAHAP 1 – K-MEANS'!G15 -> 4 | H18: ='TAHAP 1 – K-MEANS'!H15 -> 5 | I18: ='TAHAP 1 – K-MEANS'!I15 -> 4 | J18: ='TAHAP 1 – K-MEANS'!J15 -> 5 | K18: =(D18^C6)*(E18^D6)*(F18^E6)*(G18^F6)*(H18^G6)*(I18^H6)*(J18^I6) -> 4.6440565 | L18: =RANK(K18,K9:K18,0) -> 9 | M18: ='TAHAP 1 – K-MEANS'!M15 -> K3
B20: Catatan: Si dihitung via formula POWER non-linear. Rank via fungsi RANK(). Bobot = referensi AHP.

Sheet TAHAP 4 – TOPSIS
B1: TAHAP 4: VALIDASI PEMERINGKATAN — TOPSIS
B2: Semua langkah (normalisasi, pembobotan, D+, D−, Ci, Rank) = Formula Excel
B4: LANGKAH 1: NORMALISASI MATRIKS KEPUTUSAN rij = xij / √(Σ xij²)
B5: No | C5: Nama Perawat | D5: r_C1 | E5: r_C2 | F5: r_C3 | G5: r_C4 | H5: r_C5 | I5: r_C6 | J5: r_C7 | K5: D+ (Pos) | L5: D- (Neg) | M5: Ci (Kedekatan) | N5: Rank | O5: Klaster
B6: 1 | C6: ='TAHAP 3 – WP'!C9 -> Andi Setiawan | D6: ='TAHAP 3 – WP'!D9/D16 -> 0.36629484 | E6: ='TAHAP 3 – WP'!E9/E16 -> 0.32050798 | F6: ='TAHAP 3 – WP'!F9/F16 -> 0.40657856 | G6: ='TAHAP 3 – WP'!G9/G16 -> 0.36066785 | H6: ='TAHAP 3 – WP'!H9/H16 -> 0.39970403 | I6: ='TAHAP 3 – WP'!I9/I16 -> 0.32050798 | J6: ='TAHAP 3 – WP'!J9/J16 -> 0.36784039 | K6: =SQRT((D20-D30)^2+(E20-E30)^2+(F20-F30)^2+(G20-G30)^2+(H20-H30)^2+(I20-I30)^2+(J20-J30)^2) -> 0.028903896 | L6: =SQRT((D20-D31)^2+(E20-E31)^2+(F20-F31)^2+(G20-G31)^2+(H20-H31)^2+(I20-I31)^2+(J20-J31)^2) -> 0.091014558 | M6: =L6/(K6+L6) -> 0.75897041 | N6: =RANK(M6,M6:M15,0) -> 4 | O6: ='TAHAP 3 – WP'!M9 -> K1
B7: 2 | C7: ='TAHAP 3 – WP'!C10 -> Budi Santoso | D7: ='TAHAP 3 – WP'!D10/D16 -> 0.22893427 | E7: ='TAHAP 3 – WP'!E10/E16 -> 0.27472113 | F7: ='TAHAP 3 – WP'!F10/F16 -> 0.22587698 | G7: ='TAHAP 3 – WP'!G10/G16 -> 0.27050089 | H7: ='TAHAP 3 – WP'!H10/H16 -> 0.2220578 | I7: ='TAHAP 3 – WP'!I10/I16 -> 0.27472113 | J7: ='TAHAP 3 – WP'!J10/J16 -> 0.22990024 | K7: =SQRT((D21-D30)^2+(E21-E30)^2+(F21-F30)^2+(G21-G30)^2+(H21-H30)^2+(I21-I30)^2+(J21-J30)^2) -> 0.088252592 | L7: =SQRT((D21-D31)^2+(E21-E31)^2+(F21-F31)^2+(G21-G31)^2+(H21-H31)^2+(I21-I31)^2+(J21-J31)^2) -> 0.030035592 | M7: =L7/(K7+L7) -> 0.25391879 | N7: =RANK(M7,M6:M15,0) -> 8 | O7: ='TAHAP 3 – WP'!M10 -> K3
B8: 3 | C8: ='TAHAP 3 – WP'!C11 -> Citra Dewi | D8: ='TAHAP 3 – WP'!D11/D16 -> 0.41208169 | E8: ='TAHAP 3 – WP'!E11/E16 -> 0.41208169 | F8: ='TAHAP 3 – WP'!F11/F16 -> 0.36140316 | G8: ='TAHAP 3 – WP'!G11/G16 -> 0.40575134 | H8: ='TAHAP 3 – WP'!H11/H16 -> 0.39970403 | I8: ='TAHAP 3 – WP'!I11/I16 -> 0.36629484 | J8: ='TAHAP 3 – WP'!J11/J16 -> 0.41382044 | K8: =SQRT((D22-D30)^2+(E22-E30)^2+(F22-F30)^2+(G22-G30)^2+(H22-H30)^2+(I22-I30)^2+(J22-J30)^2) -> 0.0055964919 | L8: =SQRT((D22-D31)^2+(E22-E31)^2+(F22-F31)^2+(G22-G31)^2+(H22-H31)^2+(I22-I31)^2+(J22-J31)^2) -> 0.11493153 | M8: =L8/(K8+L8) -> 0.95356688 | N8: =RANK(M8,M6:M15,0) -> 1 | O8: ='TAHAP 3 – WP'!M11 -> K1
B9: 4 | C9: ='TAHAP 3 – WP'!C12 -> Dian Pratiwi | D9: ='TAHAP 3 – WP'!D12/D16 -> 0.27472113 | E9: ='TAHAP 3 – WP'!E12/E16 -> 0.22893427 | F9: ='TAHAP 3 – WP'!F12/F16 -> 0.27105237 | G9: ='TAHAP 3 – WP'!G12/G16 -> 0.22541741 | H9: ='TAHAP 3 – WP'!H12/H16 -> 0.26646936 | I9: ='TAHAP 3 – WP'!I12/I16 -> 0.22893427 | J9: ='TAHAP 3 – WP'!J12/J16 -> 0.27588029 | K9: =SQRT((D23-D30)^2+(E23-E30)^2+(F23-F30)^2+(G23-G30)^2+(H23-H30)^2+(I23-I30)^2+(J23-J30)^2) -> 0.075515722 | L9: =SQRT((D23-D31)^2+(E23-E31)^2+(F23-F31)^2+(G23-G31)^2+(H23-H31)^2+(I23-I31)^2+(J23-J31)^2) -> 0.042380326 | M9: =L9/(K9+L9) -> 0.35947198 | N9: =RANK(M9,M6:M15,0) -> 7 | O9: ='TAHAP 3 – WP'!M12 -> K3
B10: 5 | C10: ='TAHAP 3 – WP'!C13 -> Eko Wahyudi | D10: ='TAHAP 3 – WP'!D13/D16 -> 0.32050798 | E10: ='TAHAP 3 – WP'!E13/E16 -> 0.36629484 | F10: ='TAHAP 3 – WP'!F13/F16 -> 0.31622777 | G10: ='TAHAP 3 – WP'!G13/G16 -> 0.36066785 | H10: ='TAHAP 3 – WP'!H13/H16 -> 0.31088091 | I10: ='TAHAP 3 – WP'!I13/I16 -> 0.36629484 | J10: ='TAHAP 3 – WP'!J13/J16 -> 0.32186034 | K10: =SQRT((D24-D30)^2+(E24-E30)^2+(F24-F30)^2+(G24-G30)^2+(H24-H30)^2+(I24-I30)^2+(J24-J30)^2) -> 0.042380326 | L10: =SQRT((D24-D31)^2+(E24-E31)^2+(F24-F31)^2+(G24-G31)^2+(H24-H31)^2+(I24-I31)^2+(J24-J31)^2) -> 0.075515722 | M10: =L10/(K10+L10) -> 0.64052802 | N10: =RANK(M10,M6:M15,0) -> 5 | O10: ='TAHAP 3 – WP'!M13 -> K2
B11: 6 | C11: ='TAHAP 3 – WP'!C14 -> Fitri Handayani | D11: ='TAHAP 3 – WP'!D14/D16 -> 0.18314742 | E11: ='TAHAP 3 – WP'!E14/E16 -> 0.22893427 | F11: ='TAHAP 3 – WP'!F14/F16 -> 0.18070158 | G11: ='TAHAP 3 – WP'!G14/G16 -> 0.22541741 | H11: ='TAHAP 3 – WP'!H14/H16 -> 0.17764624 | I11: ='TAHAP 3 – WP'!I14/I16 -> 0.22893427 | J11: ='TAHAP 3 – WP'!J14/J16 -> 0.1839202 | K11: =SQRT((D25-D30)^2+(E25-E30)^2+(F25-F30)^2+(G25-G30)^2+(H25-H30)^2+(I25-I30)^2+(J25-J30)^2) -> 0.11137177 | L11: =SQRT((D25-D31)^2+(E25-E31)^2+(F25-F31)^2+(G25-G31)^2+(H25-H31)^2+(I25-I31)^2+(J25-J31)^2) -> 0.010992286 | M11: =L11/(K11+L11) -> 0.089832635 | N11: =RANK(M11,M6:M15,0) -> 10 | O11: ='TAHAP 3 – WP'!M14 -> K3
B12: 7 | C12: ='TAHAP 3 – WP'!C15 -> Galih Nugroho | D12: ='TAHAP 3 – WP'!D15/D16 -> 0.41208169 | E12: ='TAHAP 3 – WP'!E15/E16 -> 0.36629484 | F12: ='TAHAP 3 – WP'!F15/F16 -> 0.40657856 | G12: ='TAHAP 3 – WP'!G15/G16 -> 0.40575134 | H12: ='TAHAP 3 – WP'!H15/H16 -> 0.35529247 | I12: ='TAHAP 3 – WP'!I15/I16 -> 0.41208169 | J12: ='TAHAP 3 – WP'!J15/J16 -> 0.36784039 | K12: =SQRT((D26-D30)^2+(E26-E30)^2+(F26-F30)^2+(G26-G30)^2+(H26-H30)^2+(I26-I30)^2+(J26-J30)^2) -> 0.011686071 | L12: =SQRT((D26-D31)^2+(E26-E31)^2+(F26-F31)^2+(G26-G31)^2+(H26-H31)^2+(I26-I31)^2+(J26-J31)^2) -> 0.11073421 | M12: =L12/(K12+L12) -> 0.90454139 | N12: =RANK(M12,M6:M15,0) -> 2 | O12: ='TAHAP 3 – WP'!M15 -> K1
B13: 8 | C13: ='TAHAP 3 – WP'!C16 -> Hana Putri | D13: ='TAHAP 3 – WP'!D16/D16 -> 0.27472113 | E13: ='TAHAP 3 – WP'!E16/E16 -> 0.27472113 | F13: ='TAHAP 3 – WP'!F16/F16 -> 0.31622777 | G13: ='TAHAP 3 – WP'!G16/G16 -> 0.27050089 | H13: ='TAHAP 3 – WP'!H16/H16 -> 0.31088091 | I13: ='TAHAP 3 – WP'!I16/I16 -> 0.27472113 | J13: ='TAHAP 3 – WP'!J16/J16 -> 0.32186034 | K13: =SQRT((D27-D30)^2+(E27-E30)^2+(F27-F30)^2+(G27-G30)^2+(H27-H30)^2+(I27-I30)^2+(J27-J30)^2) -> 0.067788219 | L13: =SQRT((D27-D31)^2+(E27-E31)^2+(F27-F31)^2+(G27-G31)^2+(H27-H31)^2+(I27-I31)^2+(J27-J31)^2) -> 0.049195043 | M13: =L13/(K13+L13) -> 0.42053061 | N13: =RANK(M13,M6:M15,0) -> 6 | O13: ='TAHAP 3 – WP'!M16 -> K2
B14: 9 | C14: ='TAHAP 3 – WP'!C17 -> Indra Kusuma | D14: ='TAHAP 3 – WP'!D17/D16 -> 0.36629484 | E14: ='TAHAP 3 – WP'!E17/E16 -> 0.41208169 | F14: ='TAHAP 3 – WP'!F17/F16 -> 0.36140316 | G14: ='TAHAP 3 – WP'!G17/G16 -> 0.36066785 | H14: ='TAHAP 3 – WP'!H17/H16 -> 0.39970403 | I14: ='TAHAP 3 – WP'!I17/I16 -> 0.41208169 | J14: ='TAHAP 3 – WP'!J17/J16 -> 0.36784039 | K14: =SQRT((D28-D30)^2+(E28-E30)^2+(F28-F30)^2+(G28-G30)^2+(H28-H30)^2+(I28-I30)^2+(J28-J30)^2) -> 0.019976157 | L14: =SQRT((D28-D31)^2+(E28-E31)^2+(F28-F31)^2+(G28-G31)^2+(H28-H31)^2+(I28-I31)^2+(J28-J31)^2) -> 0.09949735 | M14: =L14/(K14+L14) -> 0.83279844 | N14: =RANK(M14,M6:M15,0) -> 3 | O14: ='TAHAP 3 – WP'!M17 -> K1
B15: 10 | C15: ='TAHAP 3 – WP'!C18 -> Joko Purnomo | D15: ='TAHAP 3 – WP'!D18/D16 -> 0.22893427 | E15: ='TAHAP 3 – WP'!E18/E16 -> 0.18314742 | F15: ='TAHAP 3 – WP'!F18/F16 -> 0.22587698 | G15: ='TAHAP 3 – WP'!G18/G16 -> 0.18033393 | H15: ='TAHAP 3 – WP'!H18/H16 -> 0.2220578 | I15: ='TAHAP 3 – WP'!I18/I16 -> 0.18314742 | J15: ='TAHAP 3 – WP'!J18/J16 -> 0.22990024 | K15: =SQRT((D29-D30)^2+(E29-E30)^2+(F29-F30)^2+(G29-G30)^2+(H29-H30)^2+(I29-I30)^2+(J29-J30)^2) -> 0.098599216 | L15: =SQRT((D29-D31)^2+(E29-E31)^2+(F29-F31)^2+(G29-G31)^2+(H29-H31)^2+(I29-I31)^2+(J29-J31)^2) -> 0.020464981 | M15: =L15/(K15+L15) -> 0.1718819 | N15: =RANK(M15,M6:M15,0) -> 9 | O15: ='TAHAP 3 – WP'!M18 -> K3
C16: √(Σxij²) Pembagi | D16: =SQRT(SUMPRODUCT('TAHAP 3 – WP'!D9:D18,'TAHAP 3 – WP'!D9:D18)) -> 21.84033 | E16: =SQRT(SUMPRODUCT('TAHAP 3 – WP'!E9:E18,'TAHAP 3 – WP'!E9:E18)) -> 21.84033 | F16: =SQRT(SUMPRODUCT('TAHAP 3 – WP'!F9:F18,'TAHAP 3 – WP'!F9:F18)) -> 22.135944 | G16: =SQRT(SUMPRODUCT('TAHAP 3 – WP'!G9:G18,'TAHAP 3 – WP'!G9:G18)) -> 22.181073 | H16: =SQRT(SUMPRODUCT('TAHAP 3 – WP'!H9:H18,'TAHAP 3 – WP'!H9:H18)) -> 22.51666 | I16: =SQRT(SUMPRODUCT('TAHAP 3 – WP'!I9:I18,'TAHAP 3 – WP'!I9:I18)) -> 21.84033 | J16: =SQRT(SUMPRODUCT('TAHAP 3 – WP'!J9:J18,'TAHAP 3 – WP'!J9:J18)) -> 21.748563
B18: LANGKAH 2: MATRIKS NORMALISASI TERBOBOT vij = rij × Wj
B19: No | C19: Nama Perawat | D19: v_C1 | E19: v_C2 | F19: v_C3 | G19: v_C4 | H19: v_C5 | I19: v_C6 | J19: v_C7
B20: 1 | C20: =C6 -> Andi Setiawan | D20: =D6*'TAHAP 3 – WP'!C6 -> 0.15315385 | E20: =E6*'TAHAP 3 – WP'!D6 -> 0.073465499 | F20: =F6*'TAHAP 3 – WP'!E6 -> 0.045799407 | G20: =G6*'TAHAP 3 – WP'!F6 -> 0.018346388 | H20: =H6*'TAHAP 3 – WP'!G6 -> 0.04502502 | I20: =I6*'TAHAP 3 – WP'!H6 -> 0.016303543 | J20: =J6*'TAHAP 3 – WP'!I6 -> 0.0094315847
B21: 2 | C21: =C7 -> Budi Santoso | D21: =D7*'TAHAP 3 – WP'!C6 -> 0.095721155 | E21: =E7*'TAHAP 3 – WP'!D6 -> 0.062970428 | F21: =F7*'TAHAP 3 – WP'!E6 -> 0.025444115 | G21: =G7*'TAHAP 3 – WP'!F6 -> 0.013759791 | H21: =H7*'TAHAP 3 – WP'!G6 -> 0.0250139 | I21: =I7*'TAHAP 3 – WP'!H6 -> 0.013974465 | J21: =J7*'TAHAP 3 – WP'!I6 -> 0.0058947404
B22: 3 | C22: =C8 -> Citra Dewi | D22: =D8*'TAHAP 3 – WP'!C6 -> 0.17229808 | E22: =E8*'TAHAP 3 – WP'!D6 -> 0.094455641 | F22: =F8*'TAHAP 3 – WP'!E6 -> 0.040710584 | G22: =G8*'TAHAP 3 – WP'!F6 -> 0.020639686 | H22: =H8*'TAHAP 3 – WP'!G6 -> 0.04502502 | I22: =I8*'TAHAP 3 – WP'!H6 -> 0.01863262 | J22: =J8*'TAHAP 3 – WP'!I6 -> 0.010610533
B23: 4 | C23: =C9 -> Dian Pratiwi | D23: =D9*'TAHAP 3 – WP'!C6 -> 0.11486539 | E23: =E9*'TAHAP 3 – WP'!D6 -> 0.052475356 | F23: =F9*'TAHAP 3 – WP'!E6 -> 0.030532938 | G23: =G9*'TAHAP 3 – WP'!F6 -> 0.011466492 | H23: =H9*'TAHAP 3 – WP'!G6 -> 0.03001668 | I23: =I9*'TAHAP 3 – WP'!H6 -> 0.011645388 | J23: =J9*'TAHAP 3 – WP'!I6 -> 0.0070736885
B24: 5 | C24: =C10 -> Eko Wahyudi | D24: =D10*'TAHAP 3 – WP'!C6 -> 0.13400962 | E24: =E10*'TAHAP 3 – WP'!D6 -> 0.08396057 | F24: =F10*'TAHAP 3 – WP'!E6 -> 0.035621761 | G24: =G10*'TAHAP 3 – WP'!F6 -> 0.018346388 | H24: =H10*'TAHAP 3 – WP'!G6 -> 0.03501946 | I24: =I10*'TAHAP 3 – WP'!H6 -> 0.01863262 | J24: =J10*'TAHAP 3 – WP'!I6 -> 0.0082526366
B25: 6 | C25: =C11 -> Fitri Handayani | D25: =D11*'TAHAP 3 – WP'!C6 -> 0.076576924 | E25: =E11*'TAHAP 3 – WP'!D6 -> 0.052475356 | F25: =F11*'TAHAP 3 – WP'!E6 -> 0.020355292 | G25: =G11*'TAHAP 3 – WP'!F6 -> 0.011466492 | H25: =H11*'TAHAP 3 – WP'!G6 -> 0.02001112 | I25: =I11*'TAHAP 3 – WP'!H6 -> 0.011645388 | J25: =J11*'TAHAP 3 – WP'!I6 -> 0.0047157924
B26: 7 | C26: =C12 -> Galih Nugroho | D26: =D12*'TAHAP 3 – WP'!C6 -> 0.17229808 | E26: =E12*'TAHAP 3 – WP'!D6 -> 0.08396057 | F26: =F12*'TAHAP 3 – WP'!E6 -> 0.045799407 | G26: =G12*'TAHAP 3 – WP'!F6 -> 0.020639686 | H26: =H12*'TAHAP 3 – WP'!G6 -> 0.04002224 | I26: =I12*'TAHAP 3 – WP'!H6 -> 0.020961698 | J26: =J12*'TAHAP 3 – WP'!I6 -> 0.0094315847
B27: 8 | C27: =C13 -> Hana Putri | D27: =D13*'TAHAP 3 – WP'!C6 -> 0.11486539 | E27: =E13*'TAHAP 3 – WP'!D6 -> 0.062970428 | F27: =F13*'TAHAP 3 – WP'!E6 -> 0.035621761 | G27: =G13*'TAHAP 3 – WP'!F6 -> 0.013759791 | H27: =H13*'TAHAP 3 – WP'!G6 -> 0.03501946 | I27: =I13*'TAHAP 3 – WP'!H6 -> 0.013974465 | J27: =J13*'TAHAP 3 – WP'!I6 -> 0.0082526366
B28: 9 | C28: =C14 -> Indra Kusuma | D28: =D14*'TAHAP 3 – WP'!C6 -> 0.15315385 | E28: =E14*'TAHAP 3 – WP'!D6 -> 0.094455641 | F28: =F14*'TAHAP 3 – WP'!E6 -> 0.040710584 | G28: =G14*'TAHAP 3 – WP'!F6 -> 0.018346388 | H28: =H14*'TAHAP 3 – WP'!G6 -> 0.04502502 | I28: =I14*'TAHAP 3 – WP'!H6 -> 0.020961698 | J28: =J14*'TAHAP 3 – WP'!I6 -> 0.0094315847
B29: 10 | C29: =C15 -> Joko Purnomo | D29: =D15*'TAHAP 3 – WP'!C6 -> 0.095721155 | E29: =E15*'TAHAP 3 – WP'!D6 -> 0.041980285 | F29: =F15*'TAHAP 3 – WP'!E6 -> 0.025444115 | G29: =G15*'TAHAP 3 – WP'!F6 -> 0.0091731939 | H29: =H15*'TAHAP 3 – WP'!G6 -> 0.0250139 | I29: =I15*'TAHAP 3 – WP'!H6 -> 0.0093163101 | J29: =J15*'TAHAP 3 – WP'!I6 -> 0.0058947404
B30: A+ (Ideal Positif) | D30: =MAX(D20:D29) -> 0.17229808 | E30: =MAX(E20:E29) -> 0.094455641 | F30: =MAX(F20:F29) -> 0.045799407 | G30: =MAX(G20:G29) -> 0.020639686 | H30: =MAX(H20:H29) -> 0.04502502 | I30: =MAX(I20:I29) -> 0.020961698 | J30: =MAX(J20:J29) -> 0.010610533
B31: A− (Ideal Negatif) | D31: =MIN(D20:D29) -> 0.076576924 | E31: =MIN(E20:E29) -> 0.041980285 | F31: =MIN(F20:F29) -> 0.020355292 | G31: =MIN(G20:G29) -> 0.0091731939 | H31: =MIN(H20:H29) -> 0.02001112 | I31: =MIN(I20:I29) -> 0.0093163101 | J31: =MIN(J20:J29) -> 0.0047157924
B33: VALIDASI KESESUAIAN PERINGKAT WP vs TOPSIS
B34: No | C34: Nama Perawat | D34: Rank WP | E34: Rank TOPSIS | F34: |ΔRank| | G34: Konsisten?
B35: 1 | C35: ='TAHAP 3 – WP'!C9 -> Andi Setiawan | D35: ='TAHAP 3 – WP'!L9 -> 4 | E35: =N6 -> 4 | F35: =ABS(D35-E35) -> 0 | G35: =IF(F35<=1,"✔ YA","✘ TIDAK") -> ✔ YA
B36: 2 | C36: ='TAHAP 3 – WP'!C10 -> Budi Santoso | D36: ='TAHAP 3 – WP'!L10 -> 8 | E36: =N7 -> 8 | F36: =ABS(D36-E36) -> 0 | G36: =IF(F36<=1,"✔ YA","✘ TIDAK") -> ✔ YA
B37: 3 | C37: ='TAHAP 3 – WP'!C11 -> Citra Dewi | D37: ='TAHAP 3 – WP'!L11 -> 1 | E37: =N8 -> 1 | F37: =ABS(D37-E37) -> 0 | G37: =IF(F37<=1,"✔ YA","✘ TIDAK") -> ✔ YA
B38: 4 | C38: ='TAHAP 3 – WP'!C12 -> Dian Pratiwi | D38: ='TAHAP 3 – WP'!L12 -> 7 | E38: =N9 -> 7 | F38: =ABS(D38-E38) -> 0 | G38: =IF(F38<=1,"✔ YA","✘ TIDAK") -> ✔ YA
B39: 5 | C39: ='TAHAP 3 – WP'!C13 -> Eko Wahyudi | D39: ='TAHAP 3 – WP'!L13 -> 5 | E39: =N10 -> 5 | F39: =ABS(D39-E39) -> 0 | G39: =IF(F39<=1,"✔ YA","✘ TIDAK") -> ✔ YA
B40: 6 | C40: ='TAHAP 3 – WP'!C14 -> Fitri Handayani | D40: ='TAHAP 3 – WP'!L14 -> 10 | E40: =N11 -> 10 | F40: =ABS(D40-E40) -> 0 | G40: =IF(F40<=1,"✔ YA","✘ TIDAK") -> ✔ YA
B41: 7 | C41: ='TAHAP 3 – WP'!C15 -> Galih Nugroho | D41: ='TAHAP 3 – WP'!L15 -> 2 | E41: =N12 -> 2 | F41: =ABS(D41-E41) -> 0 | G41: =IF(F41<=1,"✔ YA","✘ TIDAK") -> ✔ YA
B42: 8 | C42: ='TAHAP 3 – WP'!C16 -> Hana Putri | D42: ='TAHAP 3 – WP'!L16 -> 6 | E42: =N13 -> 6 | F42: =ABS(D42-E42) -> 0 | G42: =IF(F42<=1,"✔ YA","✘ TIDAK") -> ✔ YA
B43: 9 | C43: ='TAHAP 3 – WP'!C17 -> Indra Kusuma | D43: ='TAHAP 3 – WP'!L17 -> 3 | E43: =N14 -> 3 | F43: =ABS(D43-E43) -> 0 | G43: =IF(F43<=1,"✔ YA","✘ TIDAK") -> ✔ YA
...

Sheet TAHAP 5 – MODEL
B1: TAHAP 5: MODEL KONSEPTUAL – REKAPITULASI EVALUASI KINERJA PERAWAT
B2: Seluruh data = referensi formula dari sheet sebelumnya | Integrasi K-Means+AHP+WP+TOPSIS
B4: REKAPITULASI FINAL: PEMERINGKATAN KINERJA PERAWAT
B5: No | C5: Nama Perawat | D5: WP Score | E5: Rank WP | F5: TOPSIS Ci | G5: Rank TOPSIS | H5: Klaster | I5: Rank Final (Avg) | J5: Rank Final | K5: Rekomendasi
B6: 1 | C6: ='TAHAP 3 – WP'!C9 -> Andi Setiawan | D6: ='TAHAP 3 – WP'!K9 -> 7.9135552 | E6: ='TAHAP 3 – WP'!L9 -> 4 | F6: ='TAHAP 4 – TOPSIS'!M6 -> 0.75897041 | G6: ='TAHAP 4 – TOPSIS'!N6 -> 4 | H6: ='TAHAP 3 – WP'!M9 -> K1 | I6: =(D6+F6)/2 -> 4.3362628 | J6: =RANK(I6,I6:I15,0) -> 4 | K6: =IF(H6="K1","Promosi / Pengembangan Lanjut",IF(H6="K2","Pertahankan & Tingkatkan","Perlu Pembinaan Intensif")) -> Promosi / Pengembangan Lanjut
B7: 2 | C7: ='TAHAP 3 – WP'!C10 -> Budi Santoso | D7: ='TAHAP 3 – WP'!K10 -> 5.310986 | E7: ='TAHAP 3 – WP'!L10 -> 8 | F7: ='TAHAP 4 – TOPSIS'!M7 -> 0.25391879 | G7: ='TAHAP 4 – TOPSIS'!N7 -> 8 | H7: ='TAHAP 3 – WP'!M10 -> K3 | I7: =(D7+F7)/2 -> 2.7824524 | J7: =RANK(I7,I6:I15,0) -> 8 | K7: =IF(H7="K1","Promosi / Pengembangan Lanjut",IF(H7="K2","Pertahankan & Tingkatkan","Perlu Pembinaan Intensif")) -> Perlu Pembinaan Intensif
